Workbook
Name CVS100B: каталог!$Z$2:$Z$9
Name CVS100F: каталог!$AA$2:$AA$9
Name CVS100N: каталог!$AB$2:$AB$9
Name CVS160B: каталог!$AC$2:$AC$4
Name CVS160F: каталог!$AD$2:$AD$4
Name CVS160N: каталог!$AE$2:$AE$4
Name CVS250B: каталог!$AF$2:$AF$4
Name CVS250F: каталог!$AG$2:$AG$4
Name CVS250N: каталог!$AH$2:$AH$4
Name CVS400F: каталог!$AI$2:$AI$3
Name CVS400N: каталог!$AJ$2:$AJ$3
Name CVS630F: каталог!$AK$2:$AK$3
Name CVS630N: каталог!$AL$2:$AL$3
Name EZC100B: каталог!$O$2:$O$15
Name EZC100F: каталог!$P$2:$P$15
Name EZC100H: каталог!$R$2:$R$15
Name EZC100N: каталог!$Q$2:$Q$15
Name EZC250F: каталог!$S$2:$S$9
Name EZC250H: каталог!$U$2:$U$9
Name EZC250N: каталог!$T$2:$T$9
Name EZC400H: каталог!$W$2:$W$4
Name EZC400N: каталог!$V$2:$V$4
Name EZC630H: каталог!$Y$2:$Y$4
Name EZC630N: каталог!$X$2:$X$4
Name iC60H_B: каталог!$J$2:$J$16
Name iC60H_C: каталог!$L$2:$L$16
Name iC60H_D: каталог!$N$2:$N$16
Name iC60N_B: каталог!$I$2:$I$16
Name iC60N_C: каталог!$K$2:$K$16
Name iC60N_D: каталог!$M$2:$M$16
Name iDif_K: каталог!$H$2:$H$7
Name iK60N: каталог!$G$2:$G$15
Name MVS08H: каталог!$BP$2
Name MVS08N: каталог!$BO$2
Name MVS10H: каталог!$BR$2
Name MVS10N: каталог!$BQ$2
Name MVS12H: каталог!$BT$2
Name MVS12N: каталог!$BS$2
Name MVS16H: каталог!$BV$2
Name MVS16N: каталог!$BU$2
Name MVS20H: каталог!$BX$2
Name MVS20N: каталог!$BW$2
Name MVS25H: каталог!$BZ$2
Name MVS25N: каталог!$BY$2
Name MVS32H: каталог!$CB$2
Name MVS32N: каталог!$CA$2
Name MVS40H: каталог!$CD$2
Name MVS40N: каталог!$CC$2
Name NSX100B: каталог!$AM$2:$AM$3
Name NSX100F: каталог!$AN$2:$AN$3
Name NSX100H: каталог!$AP$2:$AP$3
Name NSX100L: каталог!$AR$2:$AR$3
Name NSX100N: каталог!$AO$2:$AO$3
Name NSX100S: каталог!$AQ$2:$AQ$3
Name NSX160B: каталог!$AS$2:$AS$4
Name NSX160F: каталог!$AT$2:$AT$4
Name NSX160H: каталог!$AV$2:$AV$4
Name NSX160L: каталог!$AX$2:$AX$4
Name NSX160N: каталог!$AU$2:$AU$4
Name NSX160S: каталог!$AW$2:$AW$4

Sheet выбор кабеля
S1: ГОСТ 31996-2012 | T1: ГОСТ 31996-2012 или производитель | W1: Ц02-98 | X1: Ц02-98 для алюминия - 45,65 для меди - 19,58 | Y1: Ц02-98 228 С | Z1: характеристика автомата | AD1: по ГОСТ 31996-2012 или производитель | AG1: время отключения селективного вышестоящего автомата | AK1: по ГОСТ 31996-2012 или производитель
A2: Поз. | B2: Наименование электроприемников | C2: Расчетный ток линии | D2: Ток трехфазного короткого замыкания в начале кабеля I(3)кз , кА | E2: Уставка защиты от перегрузки автоматического выключателя, Ir | F2: Выбор кабеля | P2: Проверка кабеля по ∆ U% | S2: Проверка по термической устойчивости к К.З. | AG2: Проверка по невозгоранию при К.З.
F3: тип кабеля | G3: кол-во кабелей | H3: кол-во жил | I3: сечение | J3: Iдд, А (Iдд ≥ In) | K3: коэф. на температуру среды | L3: Снижающий коэффициент при прокладке в коробах | M3: Снижающий коэффициент при прокладке в земле | N3: Iдд, А с учетом коэфф-ов (Iдд ≥ In) | O3: длина кабеля L, м | P3: r0 | Q3: x0 | R3: ∆ U% (медь, 380В) | S3: температура окр. среды Qокр | T3: длительно допустимая темп. кабеля Qдд | U3: фактическая температура окр. среды Q0 | V3: температура жилы до КЗ Qн | W3: эквивалентная постоянная времени затухания апериодической составляющей Т.К.З Таэ | X3: Постоянная характеризующая теплофизические характеристики материала, b | Y3: Величина обратная температурному коэффициенту электрического сопротивления а | Z3: время отключения основной защиты tоткл (техн. характеристика автомата) | AA3: Тепловой импульс, Втер | AB3: Коэффициент k | AC3: Тепм. жилы в начаде КЗ, Qк | AD3: Температура кабеля по условию термической устойчивости | AE3: проверка по термической устойчивости | AG3: время отключения резервной защиты t*откл | AH3: Тепловой импульс, Втер | AI3: Коэффициент k | AJ3: Тепм. жилы в конце КЗ, Qк | AK3: Температура по условию невозгорания при коротком замыканиия | AL3: проверка по условию невозгорания
B4: Питающий кабель | C4: =расчет!#REF! -> #REF! | D4: =#REF! -> #REF! | E4: 400 | F4: =расчет!#REF! -> #REF! | G4: =расчет!#REF! -> #REF! | H4: =расчет!#REF! -> #REF! | I4: =расчет!#REF! -> #REF! | J4: =расчет!#REF! -> #REF! | K4: 1 | L4: 1 | M4: 1 | N4: =J4*K4*L4*M4 -> #REF! | O4: 100 | P4: =(HLOOKUP(F4,каталог!$CG$42:$CO$60,MATCH(I4,каталог!$CF$42:$CF$60,0),0))/G4 -> #REF! | Q4: =(HLOOKUP(F4,каталог!$CS$42:$DA$57,MATCH(I4,каталог!$CR$42:$CR$57,0),0))/G4 -> #REF! | R4: =IF(расчет!#REF!=380,ROUND((1.732*C4*(P4*#REF!+Q4*SQRT(1-#REF!^2))*(O4/1000)*100)/#REF!,2),ROUND((2*C4*(P4*#REF!+Q4*SQRT(1-#REF!^2))*(O4/1000)*100)/#REF!,2)) -> #REF! | S4: 25 | T4: 70 | U4: 20 | V4: =U4+(T4-S4)*(C4/N4)^2 -> #REF! | W4: 0.02 | X4: 19.58 | Y4: 228 | Z4: 0.1 | AA4: =D4^2*(Z4+W4*(1-EXP(-(2*Z4)/W4))) -> #REF! | AB4: =(X4*AA4)/(I4*G4)^2 -> #REF! | AC4: =V4*EXP(AB4)+Y4*(EXP(AB4)-1) -> #REF! | AD4: 160 | AE4: =CONCATENATE(ROUND(AC4,),"<",AD4) -> #REF! | AF4: =IF(AC4<AD4,"ДА","НЕТ") -> #REF! | AG4: 0.2 | AH4: =D4^2*(AG4+W4*(1-EXP(-(2*AG4)/W4))) -> #REF! | AI4: =(X4*AH4)/(I4*G4)^2 -> #REF! | AJ4: =V4*EXP(AI4)+Y4*(EXP(AI4)-1) -> #REF! | AK4: 350 | AL4: =IF(AJ4<AK4,"ДА","НЕТ") -> #REF!

Sheet каталог
A1: Трансформатор | B1: Номинальная мощность, Sт.ном , кВА | C1: Потери короткого замыкания, Pк.ном , кВт | D1: Напряжение короткого замыкания, uк , % | F1: тип | G1: iK60N | H1: iDif_K | I1: iC60N_B | J1: iC60H_B | K1: iC60N_C | L1: iC60H_C | M1: iC60N_D | N1: iC60H_D | O1: EZC100B | P1: EZC100F | Q1: EZC100N | R1: EZC100H | S1: EZC250F | T1: EZC250N | U1: EZC250H | V1: EZC400N | W1: EZC400H | X1: EZC630N | Y1: EZC630H | Z1: CVS100B | AA1: CVS100F | AB1: CVS100N | AC1: CVS160B | AD1: CVS160F | AE1: CVS160N | AF1: CVS250B | AG1: CVS250F | AH1: CVS250N | AI1: CVS400F | AJ1: CVS400N | AK1: CVS630F | AL1: CVS630N | AM1: NSX100B | AN1: NSX100F | AO1: NSX100N | AP1: NSX100H | AQ1: NSX100S | AR1: NSX100L | AS1: NSX160B | AT1: NSX160F | AU1: NSX160N | AV1: NSX160H | AW1: NSX160S | AX1: NSX160L | AY1: NSX250B | AZ1: NSX250F | BA1: NSX250N | BB1: NSX250H | BC1: NSX250S | BD1: NSX250L | BE1: NSX400F | BF1: NSX400N | BG1: NSX400H | BH1: NSX400S | BI1: NSX400L | BJ1: NSX630F | BK1: NSX630N | BL1: NSX630H | BM1: NSX630S | BN1: NSX630L | BO1: MVS08N | BP1: MVS08H | BQ1: MVS10N | BR1: MVS10H | BS1: MVS12N | BT1: MVS12H | BU1: MVS16N | BV1: MVS16H | BW1: MVS20N | BX1: MVS20H | BY1: MVS25N | BZ1: MVS25H | CA1: MVS32N | CB1: MVS32H | CC1: MVS40N | CD1: MVS40H | CE1: Тип_кабеля | CF1: сечение | CG1: ВВГнг(А)-LS | CH1: ВВГнг(А)-FRLS | CI1: АВВГнг(А)-LS | CJ1: АВВГнг(А)-FRLS | CK1: ВБШвнг(А)-LS | CL1: ВБШвнг(А)-FRLS | CM1: АВБШвнг(А)-LS | CN1: АВБШвнг(А)-FRLS | CO1: ПвВнг(А)-LS | CQ1: кабель | CV1: труба | CY1: Сечение токопроводящей жилы, мм2 | CZ1: Сопротивление четырехжильного кабеля, мОм/м, при температуре жилы 65 *С | DF1: ток | DG1: контактор | DH1: Диапазон уставок тока реле
A2: ТЛС-10/6/0,4 | B2: 10 | C2: 0.28 | D2: 4.4 | F2: ном. ток | G2: 1 | H2: 6 | I2: 0.5 | J2: 0.5 | K2: 0.5 | L2: 0.5 | M2: 0.5 | N2: 0.5 | O2: 15 | P2: 15 | Q2: 15 | R2: 15 | S2: 100 | T2: 100 | U2: 100 | V2: 320 | W2: 320 | X2: 400 | Y2: 400 | Z2: 16 | AA2: 16 | AB2: 16 | AC2: 100 | AD2: 100 | AE2: 100 | AF2: 160 | AG2: 160 | AH2: 160 | AI2: 320 | AJ2: 320 | AK2: 500 | AL2: 500 | AM2: 40 | AN2: 40 | AO2: 40 | AP2: 40 | AQ2: 40 | AR2: 40 | AS2: 40 | AT2: 40 | AU2: 40 | AV2: 40 | AW2: 40 | AX2: 40 | AY2: 40 | AZ2: 40 | BA2: 40 | BB2: 40 | BC2: 40 | BD2: 40 | BE2: 400 | BF2: 400 | BG2: 400 | BH2: 400 | BI2: 400 | BJ2: 400 | BK2: 400 | BL2: 400 | BM2: 400 | BN2: 400 | BO2: 800 | BP2: 800 | BQ2: 1000 | BR2: 1000 | BS2: 1250 | BT2: 1250 | BU2: 1600 | BV2: 1600 | BW2: 2000 | BX2: 2000 | BY2: 2500 | BZ2: 2500 | CA2: 3200 | CB2: 3200 | CC2: 4000 | CD2: 4000 | CE2: ВВГнг(А)-LS | CF2: 1.5 | CG2: 19 | CH2: 19 | CI2: - | CJ2: - | CK2: 21 | CL2: 21 | CM2: - | CN2: - | CO2: 25 | CR2: нд | CS2: сеч | CT2: труба | CV2: ду | CW2: сеч | CZ2: r1 = r2 | DA2: x1 = x2 | DB2: r0 | DC2: x0 | DF2: 0.5 | DG2: LC1E06 | DH2: 0,1…0,16А | DI2: LRE01
A3: ТЛС-16/6/0,4 | B3: 16 | C3: 0.31 | D3: 3.1 | G3: 2 | H3: 10 | I3: 1 | J3: 1 | K3: 1 | L3: 1 | M3: 1 | N3: 1 | O3: 16 | P3: 16 | Q3: 16 | R3: 16 | S3: 125 | T3: 125 | U3: 125 | V3: 350 | W3: 350 | X3: 500 | Y3: 500 | Z3: 25 | AA3: 25 | AB3: 25 | AC3: 125 | AD3: 125 | AE3: 125 | AF3: 200 | AG3: 200 | AH3: 200 | AI3: 400 | AJ3: 400 | AK3: 600 | AL3: 600 | AM3: 100 | AN3: 100 | AO3: 100 | AP3: 100 | AQ3: 100 | AR3: 100 | AS3: 100 | AT3: 100 | AU3: 100 | AV3: 100 | AW3: 100 | AX3: 100 | AY3: 100 | AZ3: 100 | BA3: 100 | BB3: 100 | BC3: 100 | BD3: 100 | BJ3: 630 | BK3: 630 | BL3: 630 | BM3: 630 | BN3: 630 | CE3: ВВГнг(А)-FRLS | CF3: 2.5 | CG3: 25 | CH3: 25 | CI3: 21 | CJ3: 21 | CK3: 27 | CL3: 27 | CM3: 21 | CN3: 21 | CO3: 34 | CQ3: 2x1,5 | CR3: 7 | CS3: =0.785*CR3^2 -> 38.465 | CT3: =CS3*1.4 -> 53.851 | CU3: 16 | CV3: 10 | CW3: =0.785*CV3^2 -> 78.5 | CY3: 1.5 | CZ3: 3.54 | DA3: 0.1 | DB3: 4.24 | DC3: 1.49 | DF3: 1 | DG3: LC1E06
A4: ТЛС-25/6/0,4 | B4: 25 | C4: 0.47 | D4: 3 | G4: 3 | H4: 16 | I4: 2 | J4: 2 | K4: 2 | L4: 2 | M4: 2 | N4: 2 | O4: 20 | P4: 20 | Q4: 20 | R4: 20 | S4: 150 | T4: 150 | U4: 150 | V4: 400 | W4: 400 | X4: 600 | Y4: 600 | Z4: 32 | AA4: 32 | AB4: 32 | AC4: 160 | AD4: 160 | AE4: 160 | AF4: 250 | AG4: 250 | AH4: 250 | AS4: 160 | AT4: 160 | AU4: 160 | AV4: 160 | AW4: 160 | AX4: 160 | AY4: 160 | AZ4: 160 | BA4: 160 | BB4: 160 | BC4: 160 | BD4: 160 | CE4: АВВГнг(А)-LS | CF4: 4 | CG4: 35 | CH4: 35 | CI4: 29 | CJ4: 29 | CK4: 36 | CL4: 36 | CM4: 29 | CN4: 29 | CO4: 45 | CQ4: 2x2,5 | CR4: 8 | CS4: =0.785*CR4^2 -> 50.24 | CT4: =CS4*1.4 -> 70.336 | CU4: 16 | CV4: 12 | CW4: =0.785*CV4^2 -> 113.04 | CY4: 2.5 | CZ4: 3.54 | DA4: 0.1 | DB4: 4.24 | DC4: 1.49 | DF4: 2 | DG4: LC1E06
A5: ТЛС-40/6/0,4 | B5: 40 | C5: 0.65 | D5: 2.8 | G5: 4 | H5: 20 | I5: 3 | J5: 3 | K5: 3 | L5: 3 | M5: 3 | N5: 3 | O5: 25 | P5: 25 | Q5: 25 | R5: 25 | S5: 160 | T5: 160 | U5: 160 | Z5: 40 | AA5: 40 | AB5: 40 | AY5: 250 | AZ5: 250 | BA5: 250 | BB5: 250 | BC5: 250 | BD5: 250 | CE5: АВВГнг(А)-FRLS | CF5: 6 | CG5: 42 | CH5: 42 | CI5: 37 | CJ5: 37 | CK5: 46 | CL5: 46 | CM5: 37 | CN5: 37 | CO5: 56 | CQ5: 2x4 | CR5: 10 | CS5: =0.785*CR5^2 -> 78.5 | CT5: =CS5*1.4 -> 109.9 | CU5: 16 | CV5: 14 | CW5: =0.785*CV5^2 -> 153.86 | CY5: 4 | CZ5: 3.54 | DA5: 0.1 | DB5: 4.24 | DC5: 1.49 | DF5: 3 | DG5: LC1E06 | DJ5: =IF(DI5<=0.5,0.5,IF(DI5<=1,1,IF(DI5<=2,2,IF(DI5<=3,3,IF(DI5<=4,4,IF(DI5<=6,6,IF(DI5<=10,10,IF(DI5<=13,13,IF(DI5<=14,14,IF(DI5<=15,15,IF(DI5<=16,16,IF(DI5<=20,20,IF(DI5<=25,25,IF(DI5<=30,30,IF(DI5<=32,32,IF(DI5<=40,40,IF(DI5<=45,45,IF(DI5<=50,50,IF(DI5<=60,60,IF(DI5<=63,63,IF(DI5<=75,75,IF(DI5<=80,80,IF(DI5<=100,100,IF(DI5<=125,125,IF(DI5<=150,150,IF(DI5<=160,160,IF(DI5<=175,175,IF(DI5<=200,200,IF(DI5<=225,225,IF(DI5<=250,250,IF(DI5<=320,320,IF(DI5<=350,350,IF(DI5<=400,400,IF(DI5<=500,500,IF(DI5<=600,600,IF(DI5<=630,630)))))))))))))))))))))))))))))))))))) -> 0.5
A6: ТЛС-63/6/0,4 | B6: 63 | C6: 0.82 | D6: 2.1 | G6: 6 | H6: 25 | I6: 4 | J6: 4 | K6: 4 | L6: 4 | M6: 4 | N6: 4 | O6: 30 | P6: 30 | Q6: 30 | R6: 30 | S6: 175 | T6: 175 | U6: 175 | Z6: 50 | AA6: 50 | AB6: 50 | CE6: ВБШвнг(А)-LS | CF6: 10 | CG6: 55 | CH6: 55 | CI6: 50 | CJ6: 50 | CK6: 63 | CL6: 63 | CM6: 50 | CN6: 50 | CO6: 78 | CQ6: 2x6 | CR6: 11 | CS6: =0.785*CR6^2 -> 94.985 | CT6: =CS6*1.4 -> 132.979 | CU6: 16 | CV6: 16 | CW6: =0.785*CV6^2 -> 200.96 | CY6: 6 | CZ6: 3.54 | DA6: 0.1 | DB6: 4.24 | DC6: 1.49 | DF6: 4 | DG6: LC1E06
A7: ТЛС-100/6/0,4 | B7: 100 | C7: 2 | D7: 6 | G7: 10 | H7: 32 | I7: 6 | J7: 6 | K7: 6 | L7: 6 | M7: 6 | N7: 6 | O7: 32 | P7: 32 | Q7: 32 | R7: 32 | S7: 200 | T7: 200 | U7: 200 | Z7: 63 | AA7: 63 | AB7: 63 | CE7: ВБШвнг(А)-FRLS | CF7: 16 | CG7: 75 | CH7: 75 | CI7: 67 | CJ7: 67 | CK7: 84 | CL7: 84 | CM7: 67 | CN7: 67 | CO7: 104 | CQ7: 2x16 | CR7: 16 | CS7: =0.785*CR7^2 -> 200.96 | CT7: =CS7*1.4 -> 281.344 | CU7: 16 | CV7: 20 | CW7: =0.785*CV7^2 -> 314 | CY7: 10 | CZ7: 2.13 | DA7: 0.095 | DB7: 2.88 | DC7: 1.34 | DF7: 6 | DG7: LC1E06
A8: ТЛС-160/6/0,4 | B8: 160 | C8: 2.5 | D8: 6 | G8: 13 | I8: 10 | J8: 10 | K8: 10 | L8: 10 | M8: 10 | N8: 10 | O8: 40 | P8: 40 | Q8: 40 | R8: 40 | S8: 225 | T8: 225 | U8: 225 | Z8: 80 | AA8: 80 | AB8: 80 | CE8: АВБШвнг(А)-LS | CF8: 25 | CG8: 95 | CH8: 95 | CI8: 87 | CJ8: 87 | CK8: 112 | CL8: 112 | CM8: 87 | CN8: 87 | CO8: 141 | CQ8: 3x1,5 | CR8: 8 | CS8: =0.785*CR8^2 -> 50.24 | CT8: =CS8*1.4 -> 70.336 | CU8: 16 | CV8: 22 | CW8: =0.785*CV8^2 -> 379.94 | CY8: 16 | CZ8: 1.33 | DA8: 0.09 | DB8: 2.12 | DC8: 1.14 | DF8: 10 | DG8: LC1E12
A9: ТЛС-250/6/0,4 | B9: 250 | C9: 3.22 | D9: 6 | G9: 16 | I9: 13 | J9: 13 | K9: 13 | L9: 13 | M9: 13 | N9: 13 | O9: 45 | P9: 45 | Q9: 45 | R9: 45 | S9: 250 | T9: 250 | U9: 250 | Z9: 100 | AA9: 100 | AB9: 100 | CE9: АВБШвнг(А)-FRLS | CF9: 35 | CG9: 120 | CH9: 120 | CI9: 106 | CJ9: 106 | CK9: 137 | CL9: 137 | CM9: 106 | CN9: 106 | CO9: 172 | CQ9: 3x2,5 | CR9: 9 | CS9: =0.785*CR9^2 -> 63.585 | CT9: =CS9*1.4 -> 89.019 | CU9: 16 | CV9: 25 | CW9: =0.785*CV9^2 -> 490.625 | CY9: 25 | CZ9: 0.86 | DA9: 0.089 | DB9: 1.63 | DC9: 0.91 | DF9: 13 | DG9: LC1E18
A10: ТЛС-400/6/0,4 | B10: 400 | C10: 4.7 | D10: 6 | G10: 20 | I10: 16 | J10: 16 | K10: 16 | L10: 16 | M10: 16 | N10: 16 | O10: 50 | P10: 50 | Q10: 50 | R10: 50 | CE10: ПвВнг(А)-LS | CF10: 50 | CG10: 145 | CH10: 145 | CI10: 126 | CJ10: 126 | CK10: 167 | CL10: 167 | CM10: 126 | CN10: 126 | CO10: 209 | CQ10: 3x4 | CR10: 10 | CS10: =0.785*CR10^2 -> 78.5 | CT10: =CS10*1.4 -> 109.9 | CU10: 16 | CV10: 28 | CW10: =0.785*CV10^2 -> 615.44 | CY10: 35 | CZ10: 0.61 | DA10: 0.086 | DB10: 1.33 | DC10: 0.74 | DF10: 14 | DG10: LC1E18
A11: ТЛС-630/6/0,4 | B11: 630 | C11: 5.5 | D11: 6 | G11: 25 | I11: 20 | J11: 20 | K11: 20 | L11: 20 | M11: 20 | N11: 20 | O11: 60 | P11: 60 | Q11: 60 | R11: 60 | CF11: 70 | CG11: 180 | CH11: 180 | CI11: 161 | CJ11: 161 | CK11: 211 | CL11: 211 | CM11: 161 | CN11: 161 | CO11: 265 | CQ11: 3x6 | CR11: 12 | CS11: =0.785*CR11^2 -> 113.04 | CT11: =CS11*1.4 -> 158.256 | CU11: 16 | CV11: 32 | CW11: =0.785*CV11^2 -> 803.84 | CY11: 50 | CZ11: 0.43 | DA11: 0.086 | DB11: 1.05 | DC11: 0.58 | DF11: 15 | DG11: LC1E18
A12: ТЛС-1000/6/0,4 | B12: 1000 | C12: 8.3 | D12: 6 | G12: 32 | I12: 25 | J12: 25 | K12: 25 | L12: 25 | M12: 25 | N12: 25 | O12: 63 | P12: 63 | Q12: 63 | R12: 63 | CF12: 95 | CG12: 220 | CH12: 220 | CI12: 197 | CJ12: 197 | CK12: 261 | CL12: 261 | CM12: 197 | CN12: 197 | CO12: 327 | CQ12: 3x10 | CR12: 16 | CS12: =0.785*CR12^2 -> 200.96 | CT12: =CS12*1.4 -> 281.344 | CU12: 16 | CV12: 35 | CW12: =0.785*CV12^2 -> 961.625 | CY12: 70 | CZ12: 0.3 | DA12: 0.073 | DB12: 0.85 | DC12: 0.42 | DF12: 16 | DG12: LC1E18
A13: ТЛС-1250/6/0,4 | B13: 1250 | C13: 10.5 | D13: 6 | G13: 40 | I13: 32 | J13: 32 | K13: 32 | L13: 32 | M13: 32 | N13: 32 | O13: 75 | P13: 75 | Q13: 75 | R13: 75 | CF13: 120 | CG13: 260 | CH13: 260 | CI13: 229 | CJ13: 229 | CK13: 302 | CL13: 302 | CM13: 229 | CN13: 229 | CO13: 381 | CQ13: 3x16 | CR13: 18 | CS13: =0.785*CR13^2 -> 254.34 | CT13: =CS13*1.4 -> 356.076 | CU13: 25 | CV13: 40 | CW13: =0.785*CV13^2 -> 1256 | CY13: 95 | CZ13: 0.22 | DA13: 0.072 | DB13: 0.66 | DC13: 0.35 | DF13: 20 | DG13: LC1E25
A14: ТЛС-1600/6/0,4 | B14: 1600 | C14: 14 | D14: 6 | G14: 50 | I14: 40 | J14: 40 | K14: 40 | L14: 40 | M14: 40 | N14: 40 | O14: 80 | P14: 80 | Q14: 80 | R14: 80 | CF14: 150 | CG14: 305 | CH14: 305 | CI14: 261 | CJ14: 261 | CK14: 346 | CL14: 346 | CM14: 261 | CN14: 261 | CO14: 437 | CQ14: 3x25 | CR14: 24 | CS14: =0.785*CR14^2 -> 452.16 | CT14: =CS14*1.4 -> 633.024 | CU14: 32 | CV14: 50 | CW14: =0.785*CV14^2 -> 1962.5 | CY14: 120 | CZ14: 0.18 | DA14: 0.07 | DB14: 0.54 | DC14: 0.31 | DF14: 25 | DG14: LC1E25
A15: ТЛС-2500/6/0,4 | B15: 2500 | C15: 17 | D15: 6 | G15: 63 | I15: 50 | J15: 50 | K15: 50 | L15: 50 | M15: 50 | N15: 50 | O15: 100 | P15: 100 | Q15: 100 | R15: 100 | CF15: 185 | CG15: 350 | CH15: 350 | CI15: 302 | CJ15: 302 | CK15: 397 | CL15: 397 | CM15: 302 | CN15: 302 | CO15: 504 | CQ15: 3x35 | CR15: 26 | CS15: =0.785*CR15^2 -> 530.66 | CT15: =CS15*1.4 -> 742.924 | CU15: 32 | CY15: 150 | CZ15: 0.14 | DA15: 0.07 | DB15: 0.45 | DC15: 0.28 | DF15: 30 | DG15: LC1E32
A16: ТЛС-10/10/0,4 | B16: 10 | C16: 0.28 | D16: 4.4 | I16: 63 | J16: 63 | K16: 63 | L16: 63 | M16: 63 | N16: 63 | CF16: 240 | CG16: 472 | CH16: 472 | CI16: 359 | CJ16: 359 | CK16: 472 | CL16: 472 | CM16: 359 | CN16: 359 | CO16: 598 | CQ16: 4x1,5 | CR16: 8 | CS16: =0.785*CR16^2 -> 50.24 | CT16: =CS16*1.4 -> 70.336 | CU16: 16 | CY16: 185 | CZ16: 0.115 | DA16: 0.069 | DB16: 0.37 | DC16: 0.27 | DF16: 32 | DG16: LC1E32
A17: ТЛС-16/10/0,4 | B17: 16 | C17: 0.31 | D17: 3.1 | CF17: 300 | CG17: 542 | CH17: 542 | CI17: 424 | CJ17: 424 | CK17: 542 | CL17: 542 | CM17: 424 | CN17: 424 | CO17: 688 | CQ17: 4x2,5 | CR17: 10 | CS17: =0.785*CR17^2 -> 78.5 | CT17: =CS17*1.4 -> 109.9 | CU17: 16 | CY17: 240 | CZ17: 0.089 | DA17: 0.06 | DB17: 0.62 | DC17: 1.36 | DF17: 40 | DG17: LC1E40
A18: ТЛС-25/10/0,4 | B18: 25 | C18: 0.47 | D18: 3 | CF18: 400 | CG18: 633 | CH18: 633 | CI18: 501 | CJ18: 501 | CK18: 633 | CL18: 633 | CM18: 501 | CN18: 501 | CO18: 807 | CQ18: 4x4 | CR18: 12 | CS18: =0.785*CR18^2 -> 113.04 | CT18: =CS18*1.4 -> 158.256 | CU18: 16 | DF18: 45 | DG18: LC1E50
A19: ТЛС-40/10/0,4 | B19: 40 | C19: 0.65 | D19: 2.8 | F19: Iотл. | G19: 6 | H19: 6 | I19: 6 | J19: 10 | K19: 6 | L19: 10 | M19: 6 | N19: 10 | O19: 7.5 | P19: 10 | Q19: 18 | R19: 30 | S19: 18 | T19: 25 | U19: 36 | V19: 36 | W19: 50 | X19: 36 | Y19: 50 | Z19: 25 | AA19: 36 | AB19: 50 | AC19: 25 | AD19: 36 | AE19: 50 | AF19: 25 | AG19: 36 | AH19: 50 | AI19: 36 | AJ19: 50 | AK19: 36 | AL19: 50 | AM19: 25 | AN19: 36 | AO19: 50 | AP19: 70 | AQ19: 100 | AR19: 150 | AS19: 25 | AT19: 36 | AU19: 50 | AV19: 70 | AW19: 100 | AX19: 150 | AY19: 25 | AZ19: 36 | BA19: 50 | BB19: 70 | BC19: 100 | BD19: 150 | BE19: 36 | BF19: 50 | BG19: 70 | BH19: 100 | BI19: 150 | BJ19: 36 | BK19: 50 | BL19: 70 | BM19: 100 | BN19: 150 | BO19: 50 | BP19: 65 | BQ19: 50 | BR19: 65 | BS19: 50 | BT19: 65 | BU19: 50 | BV19: 65 | BW19: 50 | BX19: 65 | BY19: 50 | BZ19: 65 | CA19: 50 | CB19: 65 | CC19: 55 | CD19: 65 | CF19: 500 | CQ19: 4x6 | CR19: 13 | CS19: =0.785*CR19^2 -> 132.665 | CT19: =CS19*1.4 -> 185.731 | CU19: 16 | DF19: 50 | DG19: LC1E50
A20: ТЛС-63/10/0,4 | B20: 63 | C20: 0.82 | D20: 2.1 | CF20: 630 | CQ20: 4x10 | CR20: 17 | CS20: =0.785*CR20^2 -> 226.865 | CT20: =CS20*1.4 -> 317.611 | CU20: 25 | DF20: 60 | DG20: LC1E65
A21: ТЛС-100/10/0,4 | B21: 100 | C21: 2 | D21: 6 | CF21: 800 | CQ21: 4x16 | CR21: 19 | CS21: =0.785*CR21^2 -> 283.385 | CT21: =CS21*1.4 -> 396.739 | CU21: 25 | DF21: 63 | DG21: LC1E65
A22: ТЛС-160/10/0,4 | B22: 160 | C22: 2.5 | D22: 6 | F22: Номинальный ток выключателя, А | G22: Сопротивление катушки и контакта, мОм | CF22: 1000 | CQ22: 4x25 | CR22: 26 | CS22: =0.785*CR22^2 -> 530.66 | CT22: =CS22*1.4 -> 742.924 | CU22: 32 | DF22: 75 | DG22: LC1E80
A23: ТЛС-250/10/0,4 | B23: 250 | C23: 3.22 | D23: 6 | G23: rkb | H23: xkb | CQ23: 4x35 | CR23: 29 | CS23: =0.785*CR23^2 -> 660.185 | CT23: =CS23*1.4 -> 924.259 | CU23: 50 | DF23: 80 | DG23: LC1E80
A24: ТЛС-400/10/0,4 | B24: 400 | C24: 4.7 | D24: 6 | F24: 50 | G24: 7 | H24: 4.5 | CQ24: 5x1,5 | CR24: 10 | CS24: =0.785*CR24^2 -> 78.5 | CT24: =CS24*1.4 -> 109.9 | CU24: 16 | DF24: 100 | DG24: LC1E120
A25: ТЛС-630/10/0,4 | B25: 630 | C25: 5.5 | D25: 6 | F25: 70 | G25: 3.5 | H25: 2 | CQ25: 5x2,5 | CR25: 11 | CS25: =0.785*CR25^2 -> 94.985 | CT25: =CS25*1.4 -> 132.979 | CU25: 16 | DF25: 125 | DG25: LC1E160
A26: ТЛС-1000/10/0,4 | B26: 1000 | C26: 8.3 | D26: 6 | F26: 100 | G26: 2.15 | H26: 1.2 | CQ26: 5x4 | CR26: 13 | CS26: =0.785*CR26^2 -> 132.665 | CT26: =CS26*1.4 -> 185.731 | CU26: 16 | DF26: 150 | DG26: LC1E160
A27: ТЛС-1250/10/0,4 | B27: 1250 | C27: 10.5 | D27: 6 | F27: 140 | G27: 1.3 | H27: 0.7 | CQ27: 5x6 | CR27: 14 | CS27: =0.785*CR27^2 -> 153.86 | CT27: =CS27*1.4 -> 215.404 | CU27: 25 | DF27: 160 | DG27: LC1E160
A28: ТЛС-1600/10/0,4 | B28: 1600 | C28: 14 | D28: 6 | F28: 200 | G28: 1.1 | H28: 0.5 | CQ28: 5x10 | CR28: 19 | CS28: =0.785*CR28^2 -> 283.385 | CT28: =CS28*1.4 -> 396.739 | CU28: 25 | DF28: 175 | DG28: LC1E200
A29: ТЛС-2500/10/0,4 | B29: 2500 | C29: 17 | D29: 6 | F29: 400 | G29: 0.65 | H29: 0.17 | CQ29: 5x16 | CR29: 21 | CS29: =0.785*CR29^2 -> 346.185 | CT29: =CS29*1.4 -> 484.659 | CU29: 25 | DF29: 200 | DG29: LC1E200
A30: ТМГ-100/6/0,4 | B30: 100 | C30: 2 | D30: 4.5 | F30: 600 | G30: 0.41 | H30: 0.13 | CQ30: 5x25 | CR30: 29 | CS30: =0.785*CR30^2 -> 660.185 | CT30: =CS30*1.4 -> 924.259 | CU30: 50 | DF30: 225 | DG30: LC1E250
A31: ТМГ-160/6/0,4 | B31: 160 | C31: 2.8 | D31: 4.5 | F31: 1000 | G31: 0.25 | H31: 0.1 | CQ31: 5x35 | CR31: 31 | CS31: =0.785*CR31^2 -> 754.385 | CT31: =CS31*1.4 -> 1056.139 | CU31: 50 | DF31: 250 | DG31: LC1E250
A32: ТМГ-250/6/0,4 | B32: 250 | C32: 3.5 | D32: 4.5 | F32: 1600 | G32: 0.14 | H32: 0.08 | DF32: 320 | DG32: LC1E400
A33: ТМГ-400/6/0,4 | B33: 400 | C33: 6 | D33: 4.5 | F33: 2500 | G33: 0.13 | H33: 0.07 | DF33: 350 | DG33: LC1E400
A34: ТМГ-630/6/0,4 | B34: 630 | C34: 8.2 | D34: 5.5 | F34: 4000 | G34: 0.1 | H34: 0.05 | DF34: 400 | DG34: LC1E400
A35: ТМГ-1000/6/0,4 | B35: 1000 | C35: 10.5 | D35: 5.5 | DF35: 500 | DG35: LC1E500
A36: ТМГ-100/10/0,4 | B36: 100 | C36: 2 | D36: 4.5 | DF36: 600 | DG36: LC1E630
A37: ТМГ-160/10/0,4 | B37: 160 | C37: 2.8 | D37: 4.5 | DF37: 630 | DG37: LC1E630
A38: ТМГ-250/10/0,4 | B38: 250 | C38: 3.5 | D38: 4.5 | DF38: 800
A39: ТМГ-400/10/0,4 | B39: 400 | C39: 6 | D39: 4.5 | DF39: 1000
A40: ТМГ-630/10/0,4 | B40: 630 | C40: 8.2 | D40: 5.5 | DF40: 1250
...

Sheet расчет
W1: Выбор оборудования
A2: секция шин | B2: кпд | C2: Тип | D2: Наименование электроприемника | E2: Действующие нагрузки | I2: Коэффициенты | L2: Расчетные величины | O2: Эффективное число ЭП, nэ=(∑Рн)²/∑n·рн² | P2: Коэффициент расчетной нагрузки Кр | Q2: Расчетная мощность | T2: Расчетный ток, А Iр=Sр/(√3Uн) | W2: Авт. выкл. | AK2: Авт. защиты двигателя | AQ2: Мод. авт. выключатель | AV2: Диф. автомат | BB2: Авт. литой корпус
E3: Напряжение, U, В | G3: Мощность Рн=n·рн, кВт | H3: Ток I, А | I3: Использования, Ки | J3: Мощности, cosφ | K3: Реактивной мощности tgφ | L3: Ки·Рн(раб), кВт | M3: Ки·Рн(раб)·tgφ, кВт | N3: n·Рн² | Q3: Активная, кВт Рр=Кр·∑КиРн | R3: Реактивная, кВар, Qр=1,1·∑Ки·Рн·tgφ при nэ≤10; Qр=∑Ки·Рн·tgφ при nэ>10 | S3: Полная, кВА S=√Рр²+Qр² | U3: расчетный ток выключателя | V3: пусковой ток | W3: Производитель | X3: Кол-во полюсов | Y3: Easy9 Schneider Electric | Z3: Easy9 Schneider Electric | AA3: EasyPact TVS Schneider Electric | AB3: EasyPact TVS Schneider Electric | AC3: LZM Eaton | AD3: LZM Eaton | AE3: Acti9 Schneider Electric | AF3: Acti9 Schneider Electric | AG3: iDPN N Vigi Schneider Electric | AH3: iDPN N Vigi Schneider Electric | AI3: EasyPact EZC | AJ3: EasyPact EZC | AK3: DEKraft ВА431 защита двигателя | AM3: SE_GM2 | AO3: Ch_NS2 | AQ3: ТОК для модульных | AR3: DEKraft ВА105 10кА | AS3: DEKraft ВА103 6кА | AT3: SE_City9 | AU3: Ch_NB1-63 | AV3: DEKraft ДИФ-103 | AX3: SE_АВДТ | AZ3: Ch_NB2LE | BB3: DEKraft ВА-33_ | BD3: SE_CCB_F_36 кА | BF3: Ch_NM8N | BH3: КЭАЗ ВМ63 15кА | BK3: мод_hy_HGD63 | BL3: диф_hy_HRO | BM3: защ.двиг_hy_MMS32K | BO3: лит_hy_HGP | BQ3: Тип | BR3: Iном. Авт | BS3: Уставка по перегрузке | BT3: Уставка по кз | CA3: сцеплено | CB3: сцеплено
A5: ППУ | B5: 100 | C5: ПЭСПЗ | D5: Панель противопожарных устройств | E5: 380 | F5: L1, L2, L3 | G5: 0.8 | H5: =IF(E5<=230,(G5)/((E5/1000)*J5*(B5/100)),(G5)/(1.732*(E5/1000)*J5*(B5/100))) -> 1.2794841 | I5: 1 | J5: 0.95 | K5: 0.33 | L5: =I5*G5 -> 0.8 | M5: =I5*G5*K5 -> 0.264 | N5: =1*G5^2 -> 0.64 | U5: =10*1.2 -> 12 | V5: =7*H5 -> 8.9563888 | W5: Ch_NB1-63 | X5: 3Р | Y5: =IF(U5<=6,6,IF(U5<=10,10,IF(U5<=16,16,IF(U5<=20,20,IF(U5<=25,25,IF(U5<=32,32,IF(U5<=40,40,IF(U5<=50,50,IF(U5<=63,63,"др.выкл"))))))))) -> 16 | Z5: =INDEX(автоматы!$B$3:$D$11,MATCH(Y5,автоматы!$A$3:$A$11,0),MATCH(X5,кол_пол,0)) -> EZ9F34316 | AA5: =IF(U5<=0.16,0.16,IF(U5<=0.25,0.25,IF(U5<=0.4,0.4,IF(U5<=0.63,0.63,IF(U5<=1,1,IF(U5<=1.6,1.6,IF(U5<=2.5,2.5,IF(U5<=4,4,IF(U5<=6.3,6.3,IF(U5<=10,10,IF(U5<=14,14,IF(U5<=18,18,IF(U5<=23,23,IF(U5<=25,25,IF(U5<=32,32,"др.авт"))))))))))))))) -> 14 | AB5: =VLOOKUP(AA5,автоматы!$H$3:$I$17,2,0) -> GZ1 E16 | AC5: =IF(U5<=20,20,IF(U5<=25,25,IF(U5<=32,32,IF(U5<=40,40,IF(U5<=50,50,IF(U5<=63,63,IF(U5<=80,80,IF(U5<=100,100,IF(U5<=125,125,IF(U5<=160,160,IF(U5<=200,200,IF(U5<=250,250,IF(U5<=300,300,IF(U5<=320,320,IF(U5<=400,400,IF(U5<=500,500,IF(U5<=630,630,"др.авт"))))))))))))))))) -> 20 | AD5: =VLOOKUP(AC5,автоматы!$N$3:$O$19,2,0) -> LZMB1-A20-I | AE5: =IF(U5<=6,6,IF(U5<=10,10,IF(U5<=16,16,IF(U5<=20,20,IF(U5<=25,25,IF(U5<=32,32,IF(U5<=40,40,IF(U5<=50,50,IF(U5<=63,63,"др.выкл"))))))))) -> 16 | AF5: =INDEX(автоматы!$T$2:$V$15,MATCH(AE5,автоматы!$S$2:$S$15,0),MATCH(X5,автоматы!$T$1:$V$1,0)) -> iC60N C16 3P | AG5: =IF(U5<=6,6,IF(U5<=10,10,IF(U5<=16,16,IF(U5<=20,20,IF(U5<=25,25,IF(U5<=32,32,IF(U5<=40,40,"др.выкл"))))))) -> 16 | AH5: =VLOOKUP(AG5,автоматы!$Z$3:$AA$9,2,0) -> A9D31616 | AI5: =IF(U5<=15,15,IF(U5<=16,16,IF(U5<=20,20,IF(U5<=25,25,IF(U5<=32,32,IF(U5<=40,40,IF(U5<=45,45,IF(U5<=50,50,IF(U5<=60,60,IF(U5<=63,63,IF(U5<=75,75,IF(U5<=80,80,IF(U5<=100,100,IF(U5<=125,125,IF(U5<=150,150,IF(U5<=160,160,IF(U5<=175,175,IF(U5<=200,200,IF(U5<=225,225,IF(U5<=250,250,IF(U5<=320,320,IF(U5<=350,350,IF(U5<=400,400,"др.выкл"))))))))))))))))))))))) -> 15 | AJ5: =VLOOKUP(AI5,автоматы!$AE$3:$AF$26,2,0) -> EZC100F3015 | AK5: =IF(U5<=0.16,0.16,IF(U5<=0.25,0.25,IF(U5<=0.4,0.4,IF(U5<=0.63,0.63,IF(U5<=1,1,IF(U5<=1.6,1.6,IF(U5<=2.5,2.5,IF(U5<=4,4,IF(U5<=6.3,6.3,IF(U5<=10,10,IF(U5<=14,14,IF(U5<=18,18,IF(U5<=23,23,IF(U5<=25,25,IF(U5<=32,32,"др.авт"))))))))))))))) -> 14 | AL5: =VLOOKUP(AK5,DEKraft!$I$2:$J$16,2,0) -> 21230DEK | AM5: =IF(U5<=0.16,0.16,IF(U5<=0.25,0.25,IF(U5<=0.4,0.4,IF(U5<=0.63,0.63,IF(U5<=1,1,IF(U5<=1.6,1.6,IF(U5<=2.5,2.5,IF(U5<=4,4,IF(U5<=6.3,6.3,IF(U5<=10,10,IF(U5<=14,14,IF(U5<=18,18,IF(U5<=23,23,IF(U5<=25,25,IF(U5<=32,32,"др.авт"))))))))))))))) -> 14 | AN5: =VLOOKUP(AM5,systeme!$A$33:$B$47,2,0) -> GM2ME16 | AO5: =IF(U5<=0.16,0.16,IF(U5<=0.25,0.25,IF(U5<=0.4,0.4,IF(U5<=0.63,0.63,IF(U5<=1,1,IF(U5<=1.6,1.6,IF(U5<=2.5,2.5,IF(U5<=4,4,IF(U5<=6.3,6.3,IF(U5<=10,10,IF(U5<=14,14,IF(U5<=18,18,IF(U5<=23,23,IF(U5<=25,25,IF(U5<=32,32,"др.авт"))))))))))))))) -> 14 | AP5: =VLOOKUP(AO5,chint!$A$34:$B$48,2,0) -> 495082 | AQ5: =IF(U5<=6,6,IF(U5<=10,10,IF(U5<=16,16,IF(U5<=20,20,IF(U5<=25,25,IF(U5<=32,32,IF(U5<=40,40,IF(U5<=50,50,IF(U5<=63,63,"др.выкл"))))))))) -> 16 | AR5: =INDEX(DEKraft!$B$2:$D$13,MATCH(AQ5,DEKraft!$A$2:$A$13,0),MATCH(X5,DEKraft!$B$1:$D$1,0)) -> 13177DEK | AS5: =INDEX(DEKraft!$B$21:$D$32,MATCH(AQ5,DEKraft!$A$21:$A$32,0),MATCH(X5,DEKraft!$B$20:$D$20,0)) -> 12305DEK | AT5: =INDEX(systeme!$B$2:$D$10,MATCH(AQ5,systeme!$A$2:$A$10,0),MATCH(X5,systeme!$B$1:$D$1,0)) -> C9F36316 | AU5: =INDEX(chint!$B$2:$D$10,MATCH(AQ5,chint!$A$2:$A$10,0),MATCH(X5,chint!$B$1:$D$1,0)) -> 179700 | AV5: =IF(U5<=6,6,IF(U5<=10,10,IF(U5<=16,16,IF(U5<=20,20,IF(U5<=25,25,IF(U5<=32,32,IF(U5<=40,40,"др.выкл"))))))) -> 16 | AW5: =VLOOKUP(AV5,DEKraft!$A$41:$B$47,2,0) -> 16204DEK | AX5: =IF(U5<=10,10,IF(U5<=16,16,IF(U5<=20,20,IF(U5<=25,25,IF(U5<=32,32,IF(U5<=40,40,"др.выкл")))))) -> 16 | AY5: =VLOOKUP(AX5,systeme!$G$2:$H$7,2,0) -> C9D36616 | AZ5: =IF(U5<=6,6,IF(U5<=10,10,IF(U5<=16,16,IF(U5<=20,20,IF(U5<=25,25,IF(U5<=32,32,IF(U5<=40,40,"др.выкл"))))))) -> 16 | BA5: =VLOOKUP(AV5,chint!$G$2:$H$8,2,0) -> 689002 | BB5: =IF(U5<=25,25,IF(U5<=32,32,IF(U5<=40,40,IF(U5<=50,50,IF(U5<=63,63,IF(U5<=80,80,IF(U5<=100,100,IF(U5<=125,125,IF(U5<=140,140,IF(U5<=160,160,IF(U5<=200,200,IF(U5<=250,250,IF(U5<=320,320,IF(U5<=400,400,IF(U5<=500,500,IF(U5<=630,630,"др.выкл")))))))))))))))) -> 25 | BC5: =VLOOKUP(BB5,DEKraft!$I$21:$J$36,2,0) -> 28100DEK | BD5: =IF(U5<=16,16,IF(U5<=25,25,IF(U5<=32,32,IF(U5<=40,40,IF(U5<=50,50,IF(U5<=63,63,IF(U5<=80,80,IF(U5<=100,100,IF(U5<=125,125,IF(U5<=160,160,IF(U5<=200,200,IF(U5<=250,250,IF(U5<=400,400,IF(U5<=500,500,IF(U5<=600,600,"др.авт"))))))))))))))) -> 16 | BE5: =VLOOKUP(BD5,systeme!$A$16:$B$30,2,0) -> SPC100F016L3DF | BF5: =IF(U5<=16,16,IF(U5<=25,25,IF(U5<=32,32,IF(U5<=40,40,IF(U5<=50,50,IF(U5<=63,63,IF(U5<=80,80,IF(U5<=100,100,IF(U5<=125,125,IF(U5<=160,160,IF(U5<=200,200,IF(U5<=225,225,IF(U5<=250,250,IF(U5<=315,315,IF(U5<=350,350,IF(U5<=400,400,IF(U5<=500,500,IF(U5<=630,630,"др.выкл")))))))))))))))))) -> 16 | BG5: =VLOOKUP(BF5,chint!$A$14:$B$31,2,0) -> 271581 | BH5: =IF(U5<=6,6,IF(U5<=10,10,IF(U5<=16,16,IF(U5<=20,20,IF(U5<=25,25,IF(U5<=32,32,IF(U5<=40,40,IF(U5<=50,50,IF(U5<=63,63,"др.выкл"))))))))) -> 16 | BI5: =INDEX(КЭАЗ!$B$2:$E$14,MATCH(BH5,КЭАЗ!$A$2:$A$14,0),MATCH(X5,КЭАЗ!$B$1:$D$1,0)) -> kea.341959 | BJ5: =IF(U5<=6,6,IF(U5<=10,10,IF(U5<=16,16,IF(U5<=20,20,IF(U5<=25,25,IF(U5<=32,32,IF(U5<=40,40,IF(U5<=50,50,IF(U5<=63,63,IF(U5<=80,80,IF(U5<=100,100,IF(U5<=125,125,"др.выкл")))))))))))) -> 16 | BK5: =INDEX(hy!$B$2:$D$18,MATCH(BJ5,hy!$A$2:$A$18,0),MATCH(X5,hy!$B$1:$D$1,0)) -> HGD63M 3PMCS0000C 00016 | BL5: =VLOOKUP(BJ5,hy!$G$2:$H$15,2,0) -> HRO63M 1NG4С0000C00016G | BM5: =IF(U5<=0.16,0.16,IF(U5<=0.25,0.25,IF(U5<=0.4,0.4,IF(U5<=0.63,0.63,IF(U5<=1,1,IF(U5<=1.6,1.6,IF(U5<=2.5,2.5,IF(U5<=4,4,IF(U5<=6.3,6.3,IF(U5<=10,10,IF(U5<=14,14,IF(U5<=18,18,IF(U5<=23,23,IF(U5<=25,25,IF(U5<=32,32,"др.авт"))))))))))))))) -> 14 | BN5: =VLOOKUP(BM5,hy!$A$41:$B$55,2,0) -> MMS32K 0014 | BO5: =IF(U5<=100,100,IF(U5<=125,125,IF(U5<=150,150,IF(U5<=160,160,IF(U5<=175,175,IF(U5<=200,200,IF(U5<=225,225,IF(U5<=250,250,IF(U5<=300,300,IF(U5<=350,350,IF(U5<=400,400,IF(U5<=500,500,IF(U5<=630,630,IF(U5<=700,700,IF(U5<=800,800,"др.выкл"))))))))))))))) -> 100 | BP5: =VLOOKUP(BO5,hy!$A$21:$B$35,2,0) -> HGP100S-G 3PT4S0000C 00100H | BQ5: =IF($W5=автоматы!$D$45,Z5,IF($W5=автоматы!$D$46,AF5,IF($W5=автоматы!$D$47,AH5,IF($W5=автоматы!$D$48,AB5,IF($W5=автоматы!$D$49,AJ5,IF($W5=автоматы!$D$50,AD5,IF($W5=автоматы!$D$51,BI5,IF($W5=автоматы!$D$52,AR5,IF($W5=автоматы!$D$53,AS5,IF($W5=автоматы!$D$54,AW5,IF($W5=автоматы!$D$55,AL5,IF($W5=автоматы!$D$56,BC5,IF($W5=автоматы!$D$57,AT5,IF($W5=автоматы!$D$58,AY5,IF($W5=автоматы!$D$59,AN5,IF($W5=автоматы!$D$60,BE5,IF($W5=автоматы!$D$61,AU5,IF($W5=автоматы!$D$62,BA5,IF($W5=автоматы!$D$63,AP5,IF($W5=автоматы!$D$64,BG5,IF($W5=автоматы!$D$65,BK5,IF($W5=автоматы!$D$66,BL5,IF($W5=автоматы!$D$67,BN5,IF($W5=автоматы!$D$68,BP5,"др")))))))))))))))))))))))) -> 179700 | BR5: =IF($W5=автоматы!$D$45,Y5,IF($W5=автоматы!$D$46,AE5,IF($W5=автоматы!$D$47,AG5,IF($W5=автоматы!$D$48,AA5,IF($W5=автоматы!$D$49,AI5,IF($W5=автоматы!$D$50,AC5,IF($W5=автоматы!$D$51,BH5,IF($W5=автоматы!$D$52,AQ5,IF($W5=автоматы!$D$53,AQ5,IF($W5=автоматы!$D$54,AV5,IF($W5=автоматы!$D$55,AK5,IF($W5=автоматы!$D$56,BB5,IF($W5=автоматы!$D$57,AQ5,IF($W5=автоматы!$D$58,AX5,IF($W5=автоматы!$D$59,AM5,IF($W5=автоматы!$D$60,BD5,IF($W5=автоматы!$D$61,AQ5,IF($W5=автоматы!$D$62,AZ5,IF($W5=автоматы!$D$63,AO5,IF($W5=автоматы!$D$64,BF5,IF($W5=автоматы!$D$65,BJ5,IF($W5=автоматы!$D$66,BJ5,IF($W5=автоматы!$D$67,BM5,IF($W5=автоматы!$D$68,BO5,"др")))))))))))))))))))))))) -> 16 | BS5: =CONCATENATE(IF($W5=автоматы!$A$1,Y5,IF($W5=автоматы!$H$1,VLOOKUP(AA5,автоматы!$H$3:$K$17,3,0),IF($W5=автоматы!$N$1,VLOOKUP(AC5,автоматы!$N$3:$Q$19,3,0),IF($W5=автоматы!$S$17,AE5,IF($W5=автоматы!$Z$1,AG5,IF($W5=автоматы!$AE$1,AI5,"др"))))))," А") -> др А | BT5: =IF($W5=автоматы!$A$1,Y5*10,IF($W5=автоматы!$H$1,VLOOKUP(AA5,автоматы!$H$3:$K$17,4,0),IF($W5=автоматы!$N$1,VLOOKUP(AC5,автоматы!$N$3:$Q$19,4,0),IF($W5=автоматы!$S$17,AE5*10,IF($W5=автоматы!$Z$1,AG5*10,IF($W5=автоматы!$AE$1,AI5*10,"др")))))) -> др | BV5: ВВГнг(А)-LS | BW5: 1 | BX5: 5 | BY5: 2.5 | BZ5: =HLOOKUP(BV5,каталог!$CG$1:$CO$22,MATCH(BY5,каталог!$CF$1:$CF$22,0),0)*BW5 -> 25 | CA5: =CONCATENATE("н",C5,"") -> нПЭСПЗ | CB5: =CONCATENATE(BV5," ",BX5,"x",BY5) -> ВВГнг(А)-LS 5x2,5
A6: 11 | B6: 100 | C6: ШУК | D6: Шкаф управления котельной | E6: 220 | F6: L1 | G6: 1 | H6: =IF(E6<=230,(G6)/((E6/1000)*J6*(B6/100)),(G6)/(1.732*(E6/1000)*J6*(B6/100))) -> 4.5454545 | I6: 1 | J6: 1 | K6: 0 | L6: =I6*G6 -> 1 | M6: =I6*G6*K6 -> 0 | N6: =1*G6^2 -> 1 | U6: =10*1.2 -> 12 | V6: =7*H6 -> 31.818182 | W6: Ch_NB1-63 | X6: 1Р | Y6: =IF(U6<=6,6,IF(U6<=10,10,IF(U6<=16,16,IF(U6<=20,20,IF(U6<=25,25,IF(U6<=32,32,IF(U6<=40,40,IF(U6<=50,50,IF(U6<=63,63,"др.выкл"))))))))) -> 16 | Z6: =INDEX(автоматы!$B$3:$D$11,MATCH(Y6,автоматы!$A$3:$A$11,0),MATCH(X6,кол_пол,0)) -> EZ9F34116 | AA6: =IF(U6<=0.16,0.16,IF(U6<=0.25,0.25,IF(U6<=0.4,0.4,IF(U6<=0.63,0.63,IF(U6<=1,1,IF(U6<=1.6,1.6,IF(U6<=2.5,2.5,IF(U6<=4,4,IF(U6<=6.3,6.3,IF(U6<=10,10,IF(U6<=14,14,IF(U6<=18,18,IF(U6<=23,23,IF(U6<=25,25,IF(U6<=32,32,"др.авт"))))))))))))))) -> 14 | AB6: =VLOOKUP(AA6,автоматы!$H$3:$I$17,2,0) -> GZ1 E16 | AC6: =IF(U6<=20,20,IF(U6<=25,25,IF(U6<=32,32,IF(U6<=40,40,IF(U6<=50,50,IF(U6<=63,63,IF(U6<=80,80,IF(U6<=100,100,IF(U6<=125,125,IF(U6<=160,160,IF(U6<=200,200,IF(U6<=250,250,IF(U6<=300,300,IF(U6<=320,320,IF(U6<=400,400,IF(U6<=500,500,IF(U6<=630,630,"др.авт"))))))))))))))))) -> 20 | AD6: =VLOOKUP(AC6,автоматы!$N$3:$O$19,2,0) -> LZMB1-A20-I | AE6: =IF(U6<=6,6,IF(U6<=10,10,IF(U6<=16,16,IF(U6<=20,20,IF(U6<=25,25,IF(U6<=32,32,IF(U6<=40,40,IF(U6<=50,50,IF(U6<=63,63,"др.выкл"))))))))) -> 16 | AF6: =INDEX(автоматы!$T$2:$V$15,MATCH(AE6,автоматы!$S$2:$S$15,0),MATCH(X6,автоматы!$T$1:$V$1,0)) -> iC60N C16 1P | AG6: =IF(U6<=6,6,IF(U6<=10,10,IF(U6<=16,16,IF(U6<=20,20,IF(U6<=25,25,IF(U6<=32,32,IF(U6<=40,40,"др.выкл"))))))) -> 16 | AH6: =VLOOKUP(AG6,автоматы!$Z$3:$AA$9,2,0) -> A9D31616 | AI6: =IF(U6<=15,15,IF(U6<=16,16,IF(U6<=20,20,IF(U6<=25,25,IF(U6<=32,32,IF(U6<=40,40,IF(U6<=45,45,IF(U6<=50,50,IF(U6<=60,60,IF(U6<=63,63,IF(U6<=75,75,IF(U6<=80,80,IF(U6<=100,100,IF(U6<=125,125,IF(U6<=150,150,IF(U6<=160,160,IF(U6<=175,175,IF(U6<=200,200,IF(U6<=225,225,IF(U6<=250,250,IF(U6<=320,320,IF(U6<=350,350,IF(U6<=400,400,"др.выкл"))))))))))))))))))))))) -> 15 | AJ6: =VLOOKUP(AI6,автоматы!$AE$3:$AF$26,2,0) -> EZC100F3015 | AK6: =IF(U6<=0.16,0.16,IF(U6<=0.25,0.25,IF(U6<=0.4,0.4,IF(U6<=0.63,0.63,IF(U6<=1,1,IF(U6<=1.6,1.6,IF(U6<=2.5,2.5,IF(U6<=4,4,IF(U6<=6.3,6.3,IF(U6<=10,10,IF(U6<=14,14,IF(U6<=18,18,IF(U6<=23,23,IF(U6<=25,25,IF(U6<=32,32,"др.авт"))))))))))))))) -> 14 | AL6: =VLOOKUP(AK6,DEKraft!$I$2:$J$16,2,0) -> 21230DEK | AM6: =IF(U6<=0.16,0.16,IF(U6<=0.25,0.25,IF(U6<=0.4,0.4,IF(U6<=0.63,0.63,IF(U6<=1,1,IF(U6<=1.6,1.6,IF(U6<=2.5,2.5,IF(U6<=4,4,IF(U6<=6.3,6.3,IF(U6<=10,10,IF(U6<=14,14,IF(U6<=18,18,IF(U6<=23,23,IF(U6<=25,25,IF(U6<=32,32,"др.авт"))))))))))))))) -> 14 | AN6: =VLOOKUP(AM6,systeme!$A$33:$B$47,2,0) -> GM2ME16 | AO6: =IF(U6<=0.16,0.16,IF(U6<=0.25,0.25,IF(U6<=0.4,0.4,IF(U6<=0.63,0.63,IF(U6<=1,1,IF(U6<=1.6,1.6,IF(U6<=2.5,2.5,IF(U6<=4,4,IF(U6<=6.3,6.3,IF(U6<=10,10,IF(U6<=14,14,IF(U6<=18,18,IF(U6<=23,23,IF(U6<=25,25,IF(U6<=32,32,"др.авт"))))))))))))))) -> 14 | AP6: =VLOOKUP(AO6,chint!$A$34:$B$48,2,0) -> 495082 | AQ6: =IF(U6<=6,6,IF(U6<=10,10,IF(U6<=16,16,IF(U6<=20,20,IF(U6<=25,25,IF(U6<=32,32,IF(U6<=40,40,IF(U6<=50,50,IF(U6<=63,63,"др.выкл"))))))))) -> 16 | AR6: =INDEX(DEKraft!$B$2:$D$13,MATCH(AQ6,DEKraft!$A$2:$A$13,0),MATCH(X6,DEKraft!$B$1:$D$1,0)) -> 13153DEK | AS6: =INDEX(DEKraft!$B$21:$D$32,MATCH(AQ6,DEKraft!$A$21:$A$32,0),MATCH(X6,DEKraft!$B$20:$D$20,0)) -> 12273DEK | AT6: =INDEX(systeme!$B$2:$D$10,MATCH(AQ6,systeme!$A$2:$A$10,0),MATCH(X6,systeme!$B$1:$D$1,0)) -> C9F36116 | AU6: =INDEX(chint!$B$2:$D$10,MATCH(AQ6,chint!$A$2:$A$10,0),MATCH(X6,chint!$B$1:$D$1,0)) -> 179616 | AV6: =IF(U6<=6,6,IF(U6<=10,10,IF(U6<=16,16,IF(U6<=20,20,IF(U6<=25,25,IF(U6<=32,32,IF(U6<=40,40,"др.выкл"))))))) -> 16 | AW6: =VLOOKUP(AV6,DEKraft!$A$41:$B$47,2,0) -> 16204DEK | AX6: =IF(U6<=10,10,IF(U6<=16,16,IF(U6<=20,20,IF(U6<=25,25,IF(U6<=32,32,IF(U6<=40,40,"др.выкл")))))) -> 16 | AY6: =VLOOKUP(AX6,systeme!$G$2:$H$7,2,0) -> C9D36616 | AZ6: =IF(U6<=6,6,IF(U6<=10,10,IF(U6<=16,16,IF(U6<=20,20,IF(U6<=25,25,IF(U6<=32,32,IF(U6<=40,40,"др.выкл"))))))) -> 16 | BA6: =VLOOKUP(AV6,chint!$G$2:$H$8,2,0) -> 689002 | BB6: =IF(U6<=25,25,IF(U6<=32,32,IF(U6<=40,40,IF(U6<=50,50,IF(U6<=63,63,IF(U6<=80,80,IF(U6<=100,100,IF(U6<=125,125,IF(U6<=140,140,IF(U6<=160,160,IF(U6<=200,200,IF(U6<=250,250,IF(U6<=320,320,IF(U6<=400,400,IF(U6<=500,500,IF(U6<=630,630,"др.выкл")))))))))))))))) -> 25 | BC6: =VLOOKUP(BB6,DEKraft!$I$21:$J$36,2,0) -> 28100DEK | BD6: =IF(U6<=16,16,IF(U6<=25,25,IF(U6<=32,32,IF(U6<=40,40,IF(U6<=50,50,IF(U6<=63,63,IF(U6<=80,80,IF(U6<=100,100,IF(U6<=125,125,IF(U6<=160,160,IF(U6<=200,200,IF(U6<=250,250,IF(U6<=400,400,IF(U6<=500,500,IF(U6<=600,600,"др.авт"))))))))))))))) -> 16 | BE6: =VLOOKUP(BD6,systeme!$A$16:$B$30,2,0) -> SPC100F016L3DF | BF6: =IF(U6<=16,16,IF(U6<=25,25,IF(U6<=32,32,IF(U6<=40,40,IF(U6<=50,50,IF(U6<=63,63,IF(U6<=80,80,IF(U6<=100,100,IF(U6<=125,125,IF(U6<=160,160,IF(U6<=200,200,IF(U6<=225,225,IF(U6<=250,250,IF(U6<=315,315,IF(U6<=350,350,IF(U6<=400,400,IF(U6<=500,500,IF(U6<=630,630,"др.выкл")))))))))))))))))) -> 16 | BG6: =VLOOKUP(BF6,chint!$A$14:$B$31,2,0) -> 271581 | BH6: =IF(U6<=6,6,IF(U6<=10,10,IF(U6<=16,16,IF(U6<=20,20,IF(U6<=25,25,IF(U6<=32,32,IF(U6<=40,40,IF(U6<=50,50,IF(U6<=63,63,"др.выкл"))))))))) -> 16 | BI6: =INDEX(КЭАЗ!$B$2:$E$14,MATCH(BH6,КЭАЗ!$A$2:$A$14,0),MATCH(X6,КЭАЗ!$B$1:$D$1,0)) -> kea.341881 | BJ6: =IF(U6<=6,6,IF(U6<=10,10,IF(U6<=16,16,IF(U6<=20,20,IF(U6<=25,25,IF(U6<=32,32,IF(U6<=40,40,IF(U6<=50,50,IF(U6<=63,63,IF(U6<=80,80,IF(U6<=100,100,IF(U6<=125,125,"др.выкл")))))))))))) -> 16 | BK6: =INDEX(hy!$B$2:$D$18,MATCH(BJ6,hy!$A$2:$A$18,0),MATCH(X6,hy!$B$1:$D$1,0)) -> HGD63M 1PMCS0000C 00016 | BL6: =VLOOKUP(BJ6,hy!$G$2:$H$15,2,0) -> HRO63M 1NG4С0000C00016G | BM6: =IF(U6<=0.16,0.16,IF(U6<=0.25,0.25,IF(U6<=0.4,0.4,IF(U6<=0.63,0.63,IF(U6<=1,1,IF(U6<=1.6,1.6,IF(U6<=2.5,2.5,IF(U6<=4,4,IF(U6<=6.3,6.3,IF(U6<=10,10,IF(U6<=14,14,IF(U6<=18,18,IF(U6<=23,23,IF(U6<=25,25,IF(U6<=32,32,"др.авт"))))))))))))))) -> 14 | BN6: =VLOOKUP(BM6,hy!$A$41:$B$55,2,0) -> MMS32K 0014 | BO6: =IF(U6<=100,100,IF(U6<=125,125,IF(U6<=150,150,IF(U6<=160,160,IF(U6<=175,175,IF(U6<=200,200,IF(U6<=225,225,IF(U6<=250,250,IF(U6<=300,300,IF(U6<=350,350,IF(U6<=400,400,IF(U6<=500,500,IF(U6<=630,630,IF(U6<=700,700,IF(U6<=800,800,"др.выкл"))))))))))))))) -> 100 | BP6: =VLOOKUP(BO6,hy!$A$21:$B$35,2,0) -> HGP100S-G 3PT4S0000C 00100H | BQ6: =IF($W6=автоматы!$D$45,Z6,IF($W6=автоматы!$D$46,AF6,IF($W6=автоматы!$D$47,AH6,IF($W6=автоматы!$D$48,AB6,IF($W6=автоматы!$D$49,AJ6,IF($W6=автоматы!$D$50,AD6,IF($W6=автоматы!$D$51,BI6,IF($W6=автоматы!$D$52,AR6,IF($W6=автоматы!$D$53,AS6,IF($W6=автоматы!$D$54,AW6,IF($W6=автоматы!$D$55,AL6,IF($W6=автоматы!$D$56,BC6,IF($W6=автоматы!$D$57,AT6,IF($W6=автоматы!$D$58,AY6,IF($W6=автоматы!$D$59,AN6,IF($W6=автоматы!$D$60,BE6,IF($W6=автоматы!$D$61,AU6,IF($W6=автоматы!$D$62,BA6,IF($W6=автоматы!$D$63,AP6,IF($W6=автоматы!$D$64,BG6,IF($W6=автоматы!$D$65,BK6,IF($W6=автоматы!$D$66,BL6,IF($W6=автоматы!$D$67,BN6,IF($W6=автоматы!$D$68,BP6,"др")))))))))))))))))))))))) -> 179616 | BR6: =IF($W6=автоматы!$D$45,Y6,IF($W6=автоматы!$D$46,AE6,IF($W6=автоматы!$D$47,AG6,IF($W6=автоматы!$D$48,AA6,IF($W6=автоматы!$D$49,AI6,IF($W6=автоматы!$D$50,AC6,IF($W6=автоматы!$D$51,BH6,IF($W6=автоматы!$D$52,AQ6,IF($W6=автоматы!$D$53,AQ6,IF($W6=автоматы!$D$54,AV6,IF($W6=автоматы!$D$55,AK6,IF($W6=автоматы!$D$56,BB6,IF($W6=автоматы!$D$57,AQ6,IF($W6=автоматы!$D$58,AX6,IF($W6=автоматы!$D$59,AM6,IF($W6=автоматы!$D$60,BD6,IF($W6=автоматы!$D$61,AQ6,IF($W6=автоматы!$D$62,AZ6,IF($W6=автоматы!$D$63,AO6,IF($W6=автоматы!$D$64,BF6,IF($W6=автоматы!$D$65,BJ6,IF($W6=автоматы!$D$66,BJ6,IF($W6=автоматы!$D$67,BM6,IF($W6=автоматы!$D$68,BO6,"др")))))))))))))))))))))))) -> 16 | BS6: =CONCATENATE(IF($W6=автоматы!$A$1,Y6,IF($W6=автоматы!$H$1,VLOOKUP(AA6,автоматы!$H$3:$K$17,3,0),IF($W6=автоматы!$N$1,VLOOKUP(AC6,автоматы!$N$3:$Q$19,3,0),IF($W6=автоматы!$S$17,AE6,IF($W6=автоматы!$Z$1,AG6,IF($W6=автоматы!$AE$1,AI6,"др"))))))," А") -> др А | BT6: =IF($W6=автоматы!$A$1,Y6*10,IF($W6=автоматы!$H$1,VLOOKUP(AA6,автоматы!$H$3:$K$17,4,0),IF($W6=автоматы!$N$1,VLOOKUP(AC6,автоматы!$N$3:$Q$19,4,0),IF($W6=автоматы!$S$17,AE6*10,IF($W6=автоматы!$Z$1,AG6*10,IF($W6=автоматы!$AE$1,AI6*10,"др")))))) -> др | BV6: ВВГнг(А)-LS | BW6: 1 | BX6: 3 | BY6: 2.5 | BZ6: =HLOOKUP(BV6,каталог!$CG$1:$CO$22,MATCH(BY6,каталог!$CF$1:$CF$22,0),0)*BW6 -> 25 | CA6: =CONCATENATE("н",C6,"") -> нШУК | CB6: =CONCATENATE(BV6," ",BX6,"x",BY6) -> ВВГнг(А)-LS 3x2,5
A7: 11 | B7: 100 | C7: ЩУТ | D7: Щит учета тепла | E7: 220 | F7: L3 | G7: 0.5 | H7: =IF(E7<=230,(G7)/((E7/1000)*J7*(B7/100)),(G7)/(1.732*(E7/1000)*J7*(B7/100))) -> 2.2727273 | I7: 1 | J7: 1 | K7: =ROUND(SQRT(1-(J7)^2)/J7,2) -> 0 | L7: =I7*G7 -> 0.5 | M7: =I7*G7*K7 -> 0 | N7: =1*G7^2 -> 0.25 | U7: =16*1.2 -> 19.2 | V7: =7*H7 -> 15.909091 | W7: Ch_NB1-63 | X7: 1Р | Y7: =IF(U7<=6,6,IF(U7<=10,10,IF(U7<=16,16,IF(U7<=20,20,IF(U7<=25,25,IF(U7<=32,32,IF(U7<=40,40,IF(U7<=50,50,IF(U7<=63,63,"др.выкл"))))))))) -> 20 | Z7: =INDEX(автоматы!$B$3:$D$11,MATCH(Y7,автоматы!$A$3:$A$11,0),MATCH(X7,кол_пол,0)) -> EZ9F34120 | AA7: =IF(U7<=0.16,0.16,IF(U7<=0.25,0.25,IF(U7<=0.4,0.4,IF(U7<=0.63,0.63,IF(U7<=1,1,IF(U7<=1.6,1.6,IF(U7<=2.5,2.5,IF(U7<=4,4,IF(U7<=6.3,6.3,IF(U7<=10,10,IF(U7<=14,14,IF(U7<=18,18,IF(U7<=23,23,IF(U7<=25,25,IF(U7<=32,32,"др.авт"))))))))))))))) -> 23 | AB7: =VLOOKUP(AA7,автоматы!$H$3:$I$17,2,0) -> GZ1 E21 | AC7: =IF(U7<=20,20,IF(U7<=25,25,IF(U7<=32,32,IF(U7<=40,40,IF(U7<=50,50,IF(U7<=63,63,IF(U7<=80,80,IF(U7<=100,100,IF(U7<=125,125,IF(U7<=160,160,IF(U7<=200,200,IF(U7<=250,250,IF(U7<=300,300,IF(U7<=320,320,IF(U7<=400,400,IF(U7<=500,500,IF(U7<=630,630,"др.авт"))))))))))))))))) -> 20 | AD7: =VLOOKUP(AC7,автоматы!$N$3:$O$19,2,0) -> LZMB1-A20-I | AE7: =IF(U7<=6,6,IF(U7<=10,10,IF(U7<=16,16,IF(U7<=20,20,IF(U7<=25,25,IF(U7<=32,32,IF(U7<=40,40,IF(U7<=50,50,IF(U7<=63,63,"др.выкл"))))))))) -> 20 | AF7: =INDEX(автоматы!$T$2:$V$15,MATCH(AE7,автоматы!$S$2:$S$15,0),MATCH(X7,автоматы!$T$1:$V$1,0)) -> iC60N C20 1P | AG7: =IF(U7<=6,6,IF(U7<=10,10,IF(U7<=16,16,IF(U7<=20,20,IF(U7<=25,25,IF(U7<=32,32,IF(U7<=40,40,"др.выкл"))))))) -> 20 | AH7: =VLOOKUP(AG7,автоматы!$Z$3:$AA$9,2,0) -> A9D31620 | AI7: =IF(U7<=15,15,IF(U7<=16,16,IF(U7<=20,20,IF(U7<=25,25,IF(U7<=32,32,IF(U7<=40,40,IF(U7<=45,45,IF(U7<=50,50,IF(U7<=60,60,IF(U7<=63,63,IF(U7<=75,75,IF(U7<=80,80,IF(U7<=100,100,IF(U7<=125,125,IF(U7<=150,150,IF(U7<=160,160,IF(U7<=175,175,IF(U7<=200,200,IF(U7<=225,225,IF(U7<=250,250,IF(U7<=320,320,IF(U7<=350,350,IF(U7<=400,400,"др.выкл"))))))))))))))))))))))) -> 20 | AJ7: =VLOOKUP(AI7,автоматы!$AE$3:$AF$26,2,0) -> EZC100F3020 | AK7: =IF(U7<=0.16,0.16,IF(U7<=0.25,0.25,IF(U7<=0.4,0.4,IF(U7<=0.63,0.63,IF(U7<=1,1,IF(U7<=1.6,1.6,IF(U7<=2.5,2.5,IF(U7<=4,4,IF(U7<=6.3,6.3,IF(U7<=10,10,IF(U7<=14,14,IF(U7<=18,18,IF(U7<=23,23,IF(U7<=25,25,IF(U7<=32,32,"др.авт"))))))))))))))) -> 23 | AL7: =VLOOKUP(AK7,DEKraft!$I$2:$J$16,2,0) -> 21232DEK | AM7: =IF(U7<=0.16,0.16,IF(U7<=0.25,0.25,IF(U7<=0.4,0.4,IF(U7<=0.63,0.63,IF(U7<=1,1,IF(U7<=1.6,1.6,IF(U7<=2.5,2.5,IF(U7<=4,4,IF(U7<=6.3,6.3,IF(U7<=10,10,IF(U7<=14,14,IF(U7<=18,18,IF(U7<=23,23,IF(U7<=25,25,IF(U7<=32,32,"др.авт"))))))))))))))) -> 23 | AN7: =VLOOKUP(AM7,systeme!$A$33:$B$47,2,0) -> GM2ME21 | AO7: =IF(U7<=0.16,0.16,IF(U7<=0.25,0.25,IF(U7<=0.4,0.4,IF(U7<=0.63,0.63,IF(U7<=1,1,IF(U7<=1.6,1.6,IF(U7<=2.5,2.5,IF(U7<=4,4,IF(U7<=6.3,6.3,IF(U7<=10,10,IF(U7<=14,14,IF(U7<=18,18,IF(U7<=23,23,IF(U7<=25,25,IF(U7<=32,32,"др.авт"))))))))))))))) -> 23 | AP7: =VLOOKUP(AO7,chint!$A$34:$B$48,2,0) -> 495084 | AQ7: =IF(U7<=6,6,IF(U7<=10,10,IF(U7<=16,16,IF(U7<=20,20,IF(U7<=25,25,IF(U7<=32,32,IF(U7<=40,40,IF(U7<=50,50,IF(U7<=63,63,"др.выкл"))))))))) -> 20 | AR7: =INDEX(DEKraft!$B$2:$D$13,MATCH(AQ7,DEKraft!$A$2:$A$13,0),MATCH(X7,DEKraft!$B$1:$D$1,0)) -> 13154DEK | AS7: =INDEX(DEKraft!$B$21:$D$32,MATCH(AQ7,DEKraft!$A$21:$A$32,0),MATCH(X7,DEKraft!$B$20:$D$20,0)) -> 12274DEK | AT7: =INDEX(systeme!$B$2:$D$10,MATCH(AQ7,systeme!$A$2:$A$10,0),MATCH(X7,systeme!$B$1:$D$1,0)) -> C9F36120 | AU7: =INDEX(chint!$B$2:$D$10,MATCH(AQ7,chint!$A$2:$A$10,0),MATCH(X7,chint!$B$1:$D$1,0)) -> 179618 | AV7: =IF(U7<=6,6,IF(U7<=10,10,IF(U7<=16,16,IF(U7<=20,20,IF(U7<=25,25,IF(U7<=32,32,IF(U7<=40,40,"др.выкл"))))))) -> 20 | AW7: =VLOOKUP(AV7,DEKraft!$A$41:$B$47,2,0) -> 16205DEK | AX7: =IF(U7<=10,10,IF(U7<=16,16,IF(U7<=20,20,IF(U7<=25,25,IF(U7<=32,32,IF(U7<=40,40,"др.выкл")))))) -> 20 | AY7: =VLOOKUP(AX7,systeme!$G$2:$H$7,2,0) -> C9D36620 | AZ7: =IF(U7<=6,6,IF(U7<=10,10,IF(U7<=16,16,IF(U7<=20,20,IF(U7<=25,25,IF(U7<=32,32,IF(U7<=40,40,"др.выкл"))))))) -> 20 | BA7: =VLOOKUP(AV7,chint!$G$2:$H$8,2,0) -> 689003 | BB7: =IF(U7<=25,25,IF(U7<=32,32,IF(U7<=40,40,IF(U7<=50,50,IF(U7<=63,63,IF(U7<=80,80,IF(U7<=100,100,IF(U7<=125,125,IF(U7<=140,140,IF(U7<=160,160,IF(U7<=200,200,IF(U7<=250,250,IF(U7<=320,320,IF(U7<=400,400,IF(U7<=500,500,IF(U7<=630,630,"др.выкл")))))))))))))))) -> 25 | BC7: =VLOOKUP(BB7,DEKraft!$I$21:$J$36,2,0) -> 28100DEK | BD7: =IF(U7<=16,16,IF(U7<=25,25,IF(U7<=32,32,IF(U7<=40,40,IF(U7<=50,50,IF(U7<=63,63,IF(U7<=80,80,IF(U7<=100,100,IF(U7<=125,125,IF(U7<=160,160,IF(U7<=200,200,IF(U7<=250,250,IF(U7<=400,400,IF(U7<=500,500,IF(U7<=600,600,"др.авт"))))))))))))))) -> 25 | BE7: =VLOOKUP(BD7,systeme!$A$16:$B$30,2,0) -> SPC100F025L3DF | BF7: =IF(U7<=16,16,IF(U7<=25,25,IF(U7<=32,32,IF(U7<=40,40,IF(U7<=50,50,IF(U7<=63,63,IF(U7<=80,80,IF(U7<=100,100,IF(U7<=125,125,IF(U7<=160,160,IF(U7<=200,200,IF(U7<=225,225,IF(U7<=250,250,IF(U7<=315,315,IF(U7<=350,350,IF(U7<=400,400,IF(U7<=500,500,IF(U7<=630,630,"др.выкл")))))))))))))))))) -> 25 | BG7: =VLOOKUP(BF7,chint!$A$14:$B$31,2,0) -> 271583 | BH7: =IF(U7<=6,6,IF(U7<=10,10,IF(U7<=16,16,IF(U7<=20,20,IF(U7<=25,25,IF(U7<=32,32,IF(U7<=40,40,IF(U7<=50,50,IF(U7<=63,63,"др.выкл"))))))))) -> 20 | BI7: =INDEX(КЭАЗ!$B$2:$E$14,MATCH(BH7,КЭАЗ!$A$2:$A$14,0),MATCH(X7,КЭАЗ!$B$1:$D$1,0)) -> kea.341882 | BJ7: =IF(U7<=6,6,IF(U7<=10,10,IF(U7<=16,16,IF(U7<=20,20,IF(U7<=25,25,IF(U7<=32,32,IF(U7<=40,40,IF(U7<=50,50,IF(U7<=63,63,IF(U7<=80,80,IF(U7<=100,100,IF(U7<=125,125,"др.выкл")))))))))))) -> 20 | BK7: =INDEX(hy!$B$2:$D$18,MATCH(BJ7,hy!$A$2:$A$18,0),MATCH(X7,hy!$B$1:$D$1,0)) -> HGD63M 1PMCS0000C 00020 | BL7: =VLOOKUP(BJ7,hy!$G$2:$H$15,2,0) -> HRO63M 1NG4С0000C00020G | BM7: =IF(U7<=0.16,0.16,IF(U7<=0.25,0.25,IF(U7<=0.4,0.4,IF(U7<=0.63,0.63,IF(U7<=1,1,IF(U7<=1.6,1.6,IF(U7<=2.5,2.5,IF(U7<=4,4,IF(U7<=6.3,6.3,IF(U7<=10,10,IF(U7<=14,14,IF(U7<=18,18,IF(U7<=23,23,IF(U7<=25,25,IF(U7<=32,32,"др.авт"))))))))))))))) -> 23 | BN7: =VLOOKUP(BM7,hy!$A$41:$B$55,2,0) -> MMS32K 0023 | BO7: =IF(U7<=100,100,IF(U7<=125,125,IF(U7<=150,150,IF(U7<=160,160,IF(U7<=175,175,IF(U7<=200,200,IF(U7<=225,225,IF(U7<=250,250,IF(U7<=300,300,IF(U7<=350,350,IF(U7<=400,400,IF(U7<=500,500,IF(U7<=630,630,IF(U7<=700,700,IF(U7<=800,800,"др.выкл"))))))))))))))) -> 100 | BP7: =VLOOKUP(BO7,hy!$A$21:$B$35,2,0) -> HGP100S-G 3PT4S0000C 00100H | BQ7: =IF($W7=автоматы!$D$45,Z7,IF($W7=автоматы!$D$46,AF7,IF($W7=автоматы!$D$47,AH7,IF($W7=автоматы!$D$48,AB7,IF($W7=автоматы!$D$49,AJ7,IF($W7=автоматы!$D$50,AD7,IF($W7=автоматы!$D$51,BI7,IF($W7=автоматы!$D$52,AR7,IF($W7=автоматы!$D$53,AS7,IF($W7=автоматы!$D$54,AW7,IF($W7=автоматы!$D$55,AL7,IF($W7=автоматы!$D$56,BC7,IF($W7=автоматы!$D$57,AT7,IF($W7=автоматы!$D$58,AY7,IF($W7=автоматы!$D$59,AN7,IF($W7=автоматы!$D$60,BE7,IF($W7=автоматы!$D$61,AU7,IF($W7=автоматы!$D$62,BA7,IF($W7=автоматы!$D$63,AP7,IF($W7=автоматы!$D$64,BG7,IF($W7=автоматы!$D$65,BK7,IF($W7=автоматы!$D$66,BL7,IF($W7=автоматы!$D$67,BN7,IF($W7=автоматы!$D$68,BP7,"др")))))))))))))))))))))))) -> 179618 | BR7: =IF($W7=автоматы!$D$45,Y7,IF($W7=автоматы!$D$46,AE7,IF($W7=автоматы!$D$47,AG7,IF($W7=автоматы!$D$48,AA7,IF($W7=автоматы!$D$49,AI7,IF($W7=автоматы!$D$50,AC7,IF($W7=автоматы!$D$51,BH7,IF($W7=автоматы!$D$52,AQ7,IF($W7=автоматы!$D$53,AQ7,IF($W7=автоматы!$D$54,AV7,IF($W7=автоматы!$D$55,AK7,IF($W7=автоматы!$D$56,BB7,IF($W7=автоматы!$D$57,AQ7,IF($W7=автоматы!$D$58,AX7,IF($W7=автоматы!$D$59,AM7,IF($W7=автоматы!$D$60,BD7,IF($W7=автоматы!$D$61,AQ7,IF($W7=автоматы!$D$62,AZ7,IF($W7=автоматы!$D$63,AO7,IF($W7=автоматы!$D$64,BF7,IF($W7=автоматы!$D$65,BJ7,IF($W7=автоматы!$D$66,BJ7,IF($W7=автоматы!$D$67,BM7,IF($W7=автоматы!$D$68,BO7,"др")))))))))))))))))))))))) -> 20 | BS7: =CONCATENATE(IF($W7=автоматы!$A$1,Y7,IF($W7=автоматы!$H$1,VLOOKUP(AA7,автоматы!$H$3:$K$17,3,0),IF($W7=автоматы!$N$1,VLOOKUP(AC7,автоматы!$N$3:$Q$19,3,0),IF($W7=автоматы!$S$17,AE7,IF($W7=автоматы!$Z$1,AG7,IF($W7=автоматы!$AE$1,AI7,"др"))))))," А") -> др А | BT7: =IF($W7=автоматы!$A$1,Y7*10,IF($W7=автоматы!$H$1,VLOOKUP(AA7,автоматы!$H$3:$K$17,4,0),IF($W7=автоматы!$N$1,VLOOKUP(AC7,автоматы!$N$3:$Q$19,4,0),IF($W7=автоматы!$S$17,AE7*10,IF($W7=автоматы!$Z$1,AG7*10,IF($W7=автоматы!$AE$1,AI7*10,"др")))))) -> др | BV7: ВВГнг(А)-LS | BW7: 1 | BX7: 3 | BY7: 2.5 | BZ7: =HLOOKUP(BV7,каталог!$CG$1:$CO$22,MATCH(BY7,каталог!$CF$1:$CF$22,0),0)*BW7 -> 25 | CA7: =CONCATENATE("н",C7,"") -> нЩУТ | CB7: =CONCATENATE(BV7," ",BX7,"x",BY7) -> ВВГнг(А)-LS 3x2,5
A8: 11 | B8: 100 | C8: ЩУГ | D8: Щит учета газа | E8: 220 | F8: L3 | G8: 0.5 | H8: =IF(E8<=230,(G8)/((E8/1000)*J8*(B8/100)),(G8)/(1.732*(E8/1000)*J8*(B8/100))) -> 2.2727273 | I8: 1 | J8: 1 | K8: =ROUND(SQRT(1-(J8)^2)/J8,2) -> 0 | L8: =I8*G8 -> 0.5 | M8: =I8*G8*K8 -> 0 | N8: =1*G8^2 -> 0.25 | U8: =16*1.2 -> 19.2 | V8: =7*H8 -> 15.909091 | W8: Ch_NB1-63 | X8: 1Р | Y8: =IF(U8<=6,6,IF(U8<=10,10,IF(U8<=16,16,IF(U8<=20,20,IF(U8<=25,25,IF(U8<=32,32,IF(U8<=40,40,IF(U8<=50,50,IF(U8<=63,63,"др.выкл"))))))))) -> 20 | Z8: =INDEX(автоматы!$B$3:$D$11,MATCH(Y8,автоматы!$A$3:$A$11,0),MATCH(X8,кол_пол,0)) -> EZ9F34120 | AA8: =IF(U8<=0.16,0.16,IF(U8<=0.25,0.25,IF(U8<=0.4,0.4,IF(U8<=0.63,0.63,IF(U8<=1,1,IF(U8<=1.6,1.6,IF(U8<=2.5,2.5,IF(U8<=4,4,IF(U8<=6.3,6.3,IF(U8<=10,10,IF(U8<=14,14,IF(U8<=18,18,IF(U8<=23,23,IF(U8<=25,25,IF(U8<=32,32,"др.авт"))))))))))))))) -> 23 | AB8: =VLOOKUP(AA8,автоматы!$H$3:$I$17,2,0) -> GZ1 E21 | AC8: =IF(U8<=20,20,IF(U8<=25,25,IF(U8<=32,32,IF(U8<=40,40,IF(U8<=50,50,IF(U8<=63,63,IF(U8<=80,80,IF(U8<=100,100,IF(U8<=125,125,IF(U8<=160,160,IF(U8<=200,200,IF(U8<=250,250,IF(U8<=300,300,IF(U8<=320,320,IF(U8<=400,400,IF(U8<=500,500,IF(U8<=630,630,"др.авт"))))))))))))))))) -> 20 | AD8: =VLOOKUP(AC8,автоматы!$N$3:$O$19,2,0) -> LZMB1-A20-I | AE8: =IF(U8<=6,6,IF(U8<=10,10,IF(U8<=16,16,IF(U8<=20,20,IF(U8<=25,25,IF(U8<=32,32,IF(U8<=40,40,IF(U8<=50,50,IF(U8<=63,63,"др.выкл"))))))))) -> 20 | AF8: =INDEX(автоматы!$T$2:$V$15,MATCH(AE8,автоматы!$S$2:$S$15,0),MATCH(X8,автоматы!$T$1:$V$1,0)) -> iC60N C20 1P | AG8: =IF(U8<=6,6,IF(U8<=10,10,IF(U8<=16,16,IF(U8<=20,20,IF(U8<=25,25,IF(U8<=32,32,IF(U8<=40,40,"др.выкл"))))))) -> 20 | AH8: =VLOOKUP(AG8,автоматы!$Z$3:$AA$9,2,0) -> A9D31620 | AI8: =IF(U8<=15,15,IF(U8<=16,16,IF(U8<=20,20,IF(U8<=25,25,IF(U8<=32,32,IF(U8<=40,40,IF(U8<=45,45,IF(U8<=50,50,IF(U8<=60,60,IF(U8<=63,63,IF(U8<=75,75,IF(U8<=80,80,IF(U8<=100,100,IF(U8<=125,125,IF(U8<=150,150,IF(U8<=160,160,IF(U8<=175,175,IF(U8<=200,200,IF(U8<=225,225,IF(U8<=250,250,IF(U8<=320,320,IF(U8<=350,350,IF(U8<=400,400,"др.выкл"))))))))))))))))))))))) -> 20 | AJ8: =VLOOKUP(AI8,автоматы!$AE$3:$AF$26,2,0) -> EZC100F3020 | AK8: =IF(U8<=0.16,0.16,IF(U8<=0.25,0.25,IF(U8<=0.4,0.4,IF(U8<=0.63,0.63,IF(U8<=1,1,IF(U8<=1.6,1.6,IF(U8<=2.5,2.5,IF(U8<=4,4,IF(U8<=6.3,6.3,IF(U8<=10,10,IF(U8<=14,14,IF(U8<=18,18,IF(U8<=23,23,IF(U8<=25,25,IF(U8<=32,32,"др.авт"))))))))))))))) -> 23 | AL8: =VLOOKUP(AK8,DEKraft!$I$2:$J$16,2,0) -> 21232DEK | AM8: =IF(U8<=0.16,0.16,IF(U8<=0.25,0.25,IF(U8<=0.4,0.4,IF(U8<=0.63,0.63,IF(U8<=1,1,IF(U8<=1.6,1.6,IF(U8<=2.5,2.5,IF(U8<=4,4,IF(U8<=6.3,6.3,IF(U8<=10,10,IF(U8<=14,14,IF(U8<=18,18,IF(U8<=23,23,IF(U8<=25,25,IF(U8<=32,32,"др.авт"))))))))))))))) -> 23 | AN8: =VLOOKUP(AM8,systeme!$A$33:$B$47,2,0) -> GM2ME21 | AO8: =IF(U8<=0.16,0.16,IF(U8<=0.25,0.25,IF(U8<=0.4,0.4,IF(U8<=0.63,0.63,IF(U8<=1,1,IF(U8<=1.6,1.6,IF(U8<=2.5,2.5,IF(U8<=4,4,IF(U8<=6.3,6.3,IF(U8<=10,10,IF(U8<=14,14,IF(U8<=18,18,IF(U8<=23,23,IF(U8<=25,25,IF(U8<=32,32,"др.авт"))))))))))))))) -> 23 | AP8: =VLOOKUP(AO8,chint!$A$34:$B$48,2,0) -> 495084 | AQ8: =IF(U8<=6,6,IF(U8<=10,10,IF(U8<=16,16,IF(U8<=20,20,IF(U8<=25,25,IF(U8<=32,32,IF(U8<=40,40,IF(U8<=50,50,IF(U8<=63,63,"др.выкл"))))))))) -> 20 | AR8: =INDEX(DEKraft!$B$2:$D$13,MATCH(AQ8,DEKraft!$A$2:$A$13,0),MATCH(X8,DEKraft!$B$1:$D$1,0)) -> 13154DEK | AS8: =INDEX(DEKraft!$B$21:$D$32,MATCH(AQ8,DEKraft!$A$21:$A$32,0),MATCH(X8,DEKraft!$B$20:$D$20,0)) -> 12274DEK | AT8: =INDEX(systeme!$B$2:$D$10,MATCH(AQ8,systeme!$A$2:$A$10,0),MATCH(X8,systeme!$B$1:$D$1,0)) -> C9F36120 | AU8: =INDEX(chint!$B$2:$D$10,MATCH(AQ8,chint!$A$2:$A$10,0),MATCH(X8,chint!$B$1:$D$1,0)) -> 179618 | AV8: =IF(U8<=6,6,IF(U8<=10,10,IF(U8<=16,16,IF(U8<=20,20,IF(U8<=25,25,IF(U8<=32,32,IF(U8<=40,40,"др.выкл"))))))) -> 20 | AW8: =VLOOKUP(AV8,DEKraft!$A$41:$B$47,2,0) -> 16205DEK | AX8: =IF(U8<=10,10,IF(U8<=16,16,IF(U8<=20,20,IF(U8<=25,25,IF(U8<=32,32,IF(U8<=40,40,"др.выкл")))))) -> 20 | AY8: =VLOOKUP(AX8,systeme!$G$2:$H$7,2,0) -> C9D36620 | AZ8: =IF(U8<=6,6,IF(U8<=10,10,IF(U8<=16,16,IF(U8<=20,20,IF(U8<=25,25,IF(U8<=32,32,IF(U8<=40,40,"др.выкл"))))))) -> 20 | BA8: =VLOOKUP(AV8,chint!$G$2:$H$8,2,0) -> 689003 | BB8: =IF(U8<=25,25,IF(U8<=32,32,IF(U8<=40,40,IF(U8<=50,50,IF(U8<=63,63,IF(U8<=80,80,IF(U8<=100,100,IF(U8<=125,125,IF(U8<=140,140,IF(U8<=160,160,IF(U8<=200,200,IF(U8<=250,250,IF(U8<=320,320,IF(U8<=400,400,IF(U8<=500,500,IF(U8<=630,630,"др.выкл")))))))))))))))) -> 25 | BC8: =VLOOKUP(BB8,DEKraft!$I$21:$J$36,2,0) -> 28100DEK | BD8: =IF(U8<=16,16,IF(U8<=25,25,IF(U8<=32,32,IF(U8<=40,40,IF(U8<=50,50,IF(U8<=63,63,IF(U8<=80,80,IF(U8<=100,100,IF(U8<=125,125,IF(U8<=160,160,IF(U8<=200,200,IF(U8<=250,250,IF(U8<=400,400,IF(U8<=500,500,IF(U8<=600,600,"др.авт"))))))))))))))) -> 25 | BE8: =VLOOKUP(BD8,systeme!$A$16:$B$30,2,0) -> SPC100F025L3DF | BF8: =IF(U8<=16,16,IF(U8<=25,25,IF(U8<=32,32,IF(U8<=40,40,IF(U8<=50,50,IF(U8<=63,63,IF(U8<=80,80,IF(U8<=100,100,IF(U8<=125,125,IF(U8<=160,160,IF(U8<=200,200,IF(U8<=225,225,IF(U8<=250,250,IF(U8<=315,315,IF(U8<=350,350,IF(U8<=400,400,IF(U8<=500,500,IF(U8<=630,630,"др.выкл")))))))))))))))))) -> 25 | BG8: =VLOOKUP(BF8,chint!$A$14:$B$31,2,0) -> 271583 | BH8: =IF(U8<=6,6,IF(U8<=10,10,IF(U8<=16,16,IF(U8<=20,20,IF(U8<=25,25,IF(U8<=32,32,IF(U8<=40,40,IF(U8<=50,50,IF(U8<=63,63,"др.выкл"))))))))) -> 20 | BI8: =INDEX(КЭАЗ!$B$2:$E$14,MATCH(BH8,КЭАЗ!$A$2:$A$14,0),MATCH(X8,КЭАЗ!$B$1:$D$1,0)) -> kea.341882 | BJ8: =IF(U8<=6,6,IF(U8<=10,10,IF(U8<=16,16,IF(U8<=20,20,IF(U8<=25,25,IF(U8<=32,32,IF(U8<=40,40,IF(U8<=50,50,IF(U8<=63,63,IF(U8<=80,80,IF(U8<=100,100,IF(U8<=125,125,"др.выкл")))))))))))) -> 20 | BK8: =INDEX(hy!$B$2:$D$18,MATCH(BJ8,hy!$A$2:$A$18,0),MATCH(X8,hy!$B$1:$D$1,0)) -> HGD63M 1PMCS0000C 00020 | BL8: =VLOOKUP(BJ8,hy!$G$2:$H$15,2,0) -> HRO63M 1NG4С0000C00020G | BM8: =IF(U8<=0.16,0.16,IF(U8<=0.25,0.25,IF(U8<=0.4,0.4,IF(U8<=0.63,0.63,IF(U8<=1,1,IF(U8<=1.6,1.6,IF(U8<=2.5,2.5,IF(U8<=4,4,IF(U8<=6.3,6.3,IF(U8<=10,10,IF(U8<=14,14,IF(U8<=18,18,IF(U8<=23,23,IF(U8<=25,25,IF(U8<=32,32,"др.авт"))))))))))))))) -> 23 | BN8: =VLOOKUP(BM8,hy!$A$41:$B$55,2,0) -> MMS32K 0023 | BO8: =IF(U8<=100,100,IF(U8<=125,125,IF(U8<=150,150,IF(U8<=160,160,IF(U8<=175,175,IF(U8<=200,200,IF(U8<=225,225,IF(U8<=250,250,IF(U8<=300,300,IF(U8<=350,350,IF(U8<=400,400,IF(U8<=500,500,IF(U8<=630,630,IF(U8<=700,700,IF(U8<=800,800,"др.выкл"))))))))))))))) -> 100 | BP8: =VLOOKUP(BO8,hy!$A$21:$B$35,2,0) -> HGP100S-G 3PT4S0000C 00100H | BQ8: =IF($W8=автоматы!$D$45,Z8,IF($W8=автоматы!$D$46,AF8,IF($W8=автоматы!$D$47,AH8,IF($W8=автоматы!$D$48,AB8,IF($W8=автоматы!$D$49,AJ8,IF($W8=автоматы!$D$50,AD8,IF($W8=автоматы!$D$51,BI8,IF($W8=автоматы!$D$52,AR8,IF($W8=автоматы!$D$53,AS8,IF($W8=автоматы!$D$54,AW8,IF($W8=автоматы!$D$55,AL8,IF($W8=автоматы!$D$56,BC8,IF($W8=автоматы!$D$57,AT8,IF($W8=автоматы!$D$58,AY8,IF($W8=автоматы!$D$59,AN8,IF($W8=автоматы!$D$60,BE8,IF($W8=автоматы!$D$61,AU8,IF($W8=автоматы!$D$62,BA8,IF($W8=автоматы!$D$63,AP8,IF($W8=автоматы!$D$64,BG8,IF($W8=автоматы!$D$65,BK8,IF($W8=автоматы!$D$66,BL8,IF($W8=автоматы!$D$67,BN8,IF($W8=автоматы!$D$68,BP8,"др")))))))))))))))))))))))) -> 179618 | BR8: =IF($W8=автоматы!$D$45,Y8,IF($W8=автоматы!$D$46,AE8,IF($W8=автоматы!$D$47,AG8,IF($W8=автоматы!$D$48,AA8,IF($W8=автоматы!$D$49,AI8,IF($W8=автоматы!$D$50,AC8,IF($W8=автоматы!$D$51,BH8,IF($W8=автоматы!$D$52,AQ8,IF($W8=автоматы!$D$53,AQ8,IF($W8=автоматы!$D$54,AV8,IF($W8=автоматы!$D$55,AK8,IF($W8=автоматы!$D$56,BB8,IF($W8=автоматы!$D$57,AQ8,IF($W8=автоматы!$D$58,AX8,IF($W8=автоматы!$D$59,AM8,IF($W8=автоматы!$D$60,BD8,IF($W8=автоматы!$D$61,AQ8,IF($W8=автоматы!$D$62,AZ8,IF($W8=автоматы!$D$63,AO8,IF($W8=автоматы!$D$64,BF8,IF($W8=автоматы!$D$65,BJ8,IF($W8=автоматы!$D$66,BJ8,IF($W8=автоматы!$D$67,BM8,IF($W8=автоматы!$D$68,BO8,"др")))))))))))))))))))))))) -> 20 | BS8: =CONCATENATE(IF($W8=автоматы!$A$1,Y8,IF($W8=автоматы!$H$1,VLOOKUP(AA8,автоматы!$H$3:$K$17,3,0),IF($W8=автоматы!$N$1,VLOOKUP(AC8,автоматы!$N$3:$Q$19,3,0),IF($W8=автоматы!$S$17,AE8,IF($W8=автоматы!$Z$1,AG8,IF($W8=автоматы!$AE$1,AI8,"др"))))))," А") -> др А | BT8: =IF($W8=автоматы!$A$1,Y8*10,IF($W8=автоматы!$H$1,VLOOKUP(AA8,автоматы!$H$3:$K$17,4,0),IF($W8=автоматы!$N$1,VLOOKUP(AC8,автоматы!$N$3:$Q$19,4,0),IF($W8=автоматы!$S$17,AE8*10,IF($W8=автоматы!$Z$1,AG8*10,IF($W8=автоматы!$AE$1,AI8*10,"др")))))) -> др | BV8: ВВГнг(А)-LS | BW8: 1 | BX8: 3 | BY8: 2.5 | BZ8: =HLOOKUP(BV8,каталог!$CG$1:$CO$22,MATCH(BY8,каталог!$CF$1:$CF$22,0),0)*BW8 -> 25 | CA8: =CONCATENATE("н",C8,"") -> нЩУГ | CB8: =CONCATENATE(BV8," ",BX8,"x",BY8) -> ВВГнг(А)-LS 3x2,5
